Workbook
Name _pm110: Foglio2!$D$9
Name _pm1100: Foglio2!$D$17
Name _pm11000: Foglio2!$D$27
Name _pm12: Foglio2!$D$3
Name _pm13200: Foglio2!$D$28
Name _pm150: Foglio2!$D$10
Name _pm1500: Foglio2!$D$18
Name _pm16000: Foglio2!$D$29
Name _pm18: Foglio2!$D$4
Name _pm1850: Foglio2!$D$19
Name _pm220: Foglio2!$D$11
Name _pm2200: Foglio2!$D$20
Name _pm25: Foglio2!$D$5
Name _pm300: Foglio2!$D$12
Name _pm3000: Foglio2!$D$21
Name _pm37: Foglio2!$D$6
Name _pm3700: Foglio2!$D$22
Name _pm400: Foglio2!$D$13
Name _pm4500: Foglio2!$D$23
Name _pm55: Foglio2!$D$7
Name _pm550: Foglio2!$D$14
Name _pm5500: Foglio2!$D$24
Name _pm75: Foglio2!$D$8
Name _pm750: Foglio2!$D$15
Name _pm7500: Foglio2!$D$25
Name _pm9000: Foglio2!$D$26
Name _pm920: Foglio2!$D$16

Sheet Foglio1
A1: Project ° | B1: INTERNAL ORDER CONF NR | C1: Link to PE folder | D1: CUSTOMER | E1: FINAL CUSTOMER | F1: PLANT | G1: DESCRIPTION | H1: Location | I1: Vendor | J1: YEAR | K1: Project Engineer | L1: DELIVERY | M1: REMARKS | N1: MOTOR & SENSOR LIST DELIVERED TO PURCHASE DEPT. AND TO CUSTOMER | O1: PROJECT STATUS | P1: FOLDER NAME | Q1: Column17 | R1: Column18 | S1: Column19
A2: ARC00001 | B2: IT00125COC00045 | C2: - | D2: A.R.C.E.M.I. IMPIANTI | E2: FLSMIDTH A/S | F2: UNACEM ATOCONGO | G2: 7 COCLEE | H2: PERU | I2: ARCEMI | J2: 2025 | K2: Lovat | N2: - | P2: ARC00001-A.R.C.E.M.I. IMPIANTI-FLSMIDTH A/S-UNACEM ATOCONGO-2025
A3: ARC00002 | C3: - | D3: A.R.C.E.M.I. IMPIANTI | E3: UNICALCE | G3: NASTRO BORDERBAND + PULITORE A CATENA | I3: ARCEMI | J3: 2025 | K3: Lovat | N3: - | P3: ARC00002-A.R.C.E.M.I. IMPIANTI-UNICALCE--2025
A4: ARC00003 | C4: - | D4: A.R.C.E.M.I. IMPIANTI | E4: A2A AMBIENTE SPA | G4: N°1 VALVOLA ROTANTE + ACCESSORI | I4: ARCEMI | J4: 2025 | K4: Lovat | N4: - | P4: ARC00003-A.R.C.E.M.I. IMPIANTI-A2A AMBIENTE SPA--2025
A5: ARC00004 | D5: A.R.C.E.M.I. IMPIANTI | E5: PROMOVAL | G5: REDLER EKF | I5: ARCEMI | J5: 2025 | K5: Lovat | N5: - | P5: ARC00004-A.R.C.E.M.I. IMPIANTI-PROMOVAL--2025
A6: ARC00005 | C6: - | D6: A.R.C.E.M.I. IMPIANTI | E6: COLACEM | F6: TUNISI | G6: Redler KSF | H6: TUNISIA | I6: ARCEMI | J6: 2025 | K6: Lovat | P6: ARC00005-A.R.C.E.M.I. IMPIANTI-COLACEM-TUNISI-2025
A7: ARC00006 | C7: - | D7: A.R.C.E.M.I. IMPIANTI | E7: INDUSTRIA CALCE CASERTANA | G7: ELEVATORE A CATENE | H7: ITALY | I7: ARCEMI | J7: 2025 | K7: Lovat | P7: ARC00006-A.R.C.E.M.I. IMPIANTI-INDUSTRIA CALCE CASERTANA--2025
A8: ARC00007 | C8: - | D8: A.R.C.E.M.I. IMPIANTI | F8: Calce Slovacchia | G8: ELEVATORE A CATENE | H8: SLOVACCHIA | I8: ARCEMI | J8: 2025 | K8: Lovat | P8: ARC00007-A.R.C.E.M.I. IMPIANTI--Calce Slovacchia-2025
A9: 1190 | B9: TM 07-04-09-2023-Aarati-R0 | C9: link | D9: AARTI ALCHEMIE FINECHEM PVT. LTD | F9: FHS | H9: INDIA | I9: INDIA | J9: 2023 | K9: Pannunzio | L9: 45412 | N9: TRM INDIA | O9: Completed | P9: 1190-AARTI ALCHEMIE FINECHEM PVT. LTD--FHS-2023
A10: 1203 | B10: TM 18- 30.01.2024- Aarati-ASH hand – R2 | C10: link | D10: AARTI ALCHEMIE FINECHEM PVT. LTD | F10: FLY AHS | G10: AHS FOR FLY ASH | H10: INDIA | I10: INDIA | J10: 2024 | K10: Pannunzio | L10: ?????? | N10: TRM CHN | O10: Compleded | P10: 1203-AARTI ALCHEMIE FINECHEM PVT. LTD--FLY AHS -2024
A11: 1230 | B11: TM 42 – 23.03.2024 -Aarti Grate Ash – R1 | C11: link | D11: AARTI ALCHEMIE FINECHEM PVT. LTD | F11: GRATE AHS | G11: AHS FOR FLY ASH | H11: INDIA | I11: INDIA | J11: 2024 | K11: Pannunzio | L11: ?????? | M11: ? | N11: TRM CHN | O11: Compleded | P11: 1230-AARTI ALCHEMIE FINECHEM PVT. LTD--GRATE AHS -2024
A12: IT0012025TRT00001 | B12: TM492024-AARTI IND LTD-JHAGADIA-TECHNO COMMERCIAL PROPOSAL -R5 05.12.24 | C12: link | D12: AARTI INDUSTRIES LTD | F12: JHAGADIA | G12: FHS | H12: INDIA | I12: INDIA | J12: 2025 | K12: Pannunzio | L12: 45823 | N12: YES | O12: Compleded | P12: IT0012025TRT00001-AARTI INDUSTRIES LTD--JHAGADIA-2025
A13: 1202 | B13: TM 32- 09.02.2024- AB MAURI -R3 | C13: - | D13: AB MAURI | E13: AB MAURI PILIBHIT | F13: FHS | H13: INDIA | I13: INDIA | J13: 2024 | K13: Pannunzio | L13: 45565 | N13: YES | O13: Compleded | P13: 1202-AB MAURI-AB MAURI PILIBHIT-FHS--2024
A14: IT0012025TRT00094 | C14: - | D14: ADVANCE FIBER | F14: NEW SPB LINE-1500 | G14: CHIPPING LINE AND STORAGE | H14: THAILAND | I14: CINA | J14: 2025 | K14: Pannunzio | L14: - | N14: NO | P14: IT0012025TRT00094-ADVANCE FIBER--NEW SPB LINE-1500-2025
A15: IT0012025TRT00141 | B15: TM9424-FV- BECIS-AGARTAS, SANAND GUJARAT – FUEL & ASH HANDLING SYSTEM – R3 | C15: link | D15: AGARTAS | F15: SANAND GUJARAT | G15: FHS + AHS | H15: INDIA | I15: INDIA | J15: 2025 | K15: Pannunzio | L15: 46006 | M15: FHS: 1 TKK19; 1TKK24; 1COC; 2 COC DOS ASH: 3 ATC; 1 TK?? | N15: NO | O15: LAYOUT TO BE APPROVED | P15: IT0012025TRT00141-AGARTAS--SANAND GUJARAT-2025
A16: 1146 | B16: IT00123COC00387 | C16: link | D16: AGT | E16: AGT | F16: ANTALIA | G16: SCREW INOX | H16: TURKIYE | I16: ITALIA | J16: 2023 | K16: Brugnoli | L16: 45198 | N16: YES | P16: 1146-AGT-AGT-ANTALIA-2023
A17: IT0012025TRT00023 | C17: - | D17: AGT | F17: AGT | G17: NEW CHIPS STORAGE | H17: TURKEY | J17: 2025 | K17: Brugnoli | N17: - | P17: IT0012025TRT00023-AGT--AGT-2025
A18: 1150 | B18: IT00123COC00444 | C18: - | D18: ALFAWOOD | E18: ALFAWOOD | F18: NEVROKOPI | H18: GREECE | I18: ITALIA | J18: 2023 | K18: Lorusso | L18: 45187 | N18: YES | P18: 1150-ALFAWOOD-ALFAWOOD-NEVROKOPI--2023
A19: 768 | B19: AT445 | C19: link | D19: ARAUCO | F19: BRASIL | H19: BRASIL | J19: 2017 | K19: Bonazzoli | L19: 43017 | N19: YES | O19: Completato | P19: 768-ARAUCO--BRASIL--2017
A20: IT0012025TRT00098 | B20: IT00125COC00123 | C20: link | D20: ARKH | E20: PACK | F20: MDF3 | G20: CHIPS STORAGE & HANDLING | H20: DUBAI | I20: ITALIA | J20: 2025 | K20: Pannunzio | N20: NO | P20: IT0012025TRT00098-ARKH-PACK-MDF3-2025
A21: IT0012024TRT00293 | B21: IT00125COC00125 | C21: link | D21: ARKH | E21: PACK | F21: MDF2 | G21: CHIPS STORAGE & HANDLING | H21: DUBAI | I21: ITALIA | J21: 2025 | K21: Pannunzio | N21: NO | P21: IT0012024TRT00293-ARKH-PACK-MDF2-2025
A22: 816 | B22: AU245 | C22: link | D22: ARMOR PANNEAUX | E22: ARMOR PANNEAUX | F22: ARMOR PANNEAUX | G22: SERRANDA RICAMBIO | H22: FRANCE | J22: 2018 | K22: E. Vrioni | L22: 43256 | N22: YES | O22: Completato | P22: 816-ARMOR PANNEAUX-ARMOR PANNEAUX-ARMOR PANNEAUX-2018
A23: IT0012024TRT00266 | B23: IT00124COC01244 | C23: - | D23: AUSTRALIAN PANELS | E23: BORG | F23: BORG FLAKING AREA PB GAMBIER | H23: AUSTRALIA | I23: CINA | J23: 2025 | K23: Franzini | L23: 45749 | N23: YES | O23: Completato | P23: IT0012024TRT00266-AUSTRALIAN PANELS-BORG-BORG FLAKING AREA PB GAMBIER--2025
A24: 1113 | B24: TRM CHN | C24: link | D24: BA RIA SERECE | F24: SOYA MEAL | H24: VIETNAM | I24: ITALIA | J24: 2023 | K24: - | N24: - | P24: 1113-BA RIA SERECE--SOYA MEAL-2023
A25: 1016 | B25: IT00121COC00490 | C25: link | D25: BERSEY | F25: STARWOOD | G25: DOSING BUNKER | H25: TURKIYE | I25: ITALIA | J25: 2021 | K25: Fragale | L25: 44502 | N25: YES | P25: 1016-BERSEY--STARWOOD-2021
A26: 1016 | B26: IT00121COC00771 | C26: link | D26: BERSEY | F26: STARWOOD | G26: DOSING BUNKER (one more) | H26: TURKIYE | I26: ITALIA | J26: 2021 | K26: Fragale | L26: 44656 | N26: YES | P26: 1016-BERSEY--STARWOOD-2021
A27: 1030 | B27: IT00121COC00763 | C27: link | D27: BERSEY | F27: KRASNI YAKOR | G27: BOILER BIOMASS INFEED SYSTEM TKK WCH | H27: RUSSIA | I27: ITALIA | J27: 2021 | K27: Longari | L27: 44671 | N27: YES | O27: Completato | P27: 1030-BERSEY--KRASNI YAKOR-2021
A28: 965 | B28: IT00120COC00660 | C28: link | D28: BIOSYL | F28: BIOSYL | H28: FRANCE | I28: ITALIA | J28: 2020 | K28: Franzini | L28: 44288 | N28: YES | O28: Completato | P28: 965-BIOSYL--BIOSYL-2020
A29: 1127 | B29: IT00123COC00035 | C29: - | D29: BIOSYLVA | F29: BIOSYL I | H29: FRANCE | I29: ITALIA | J29: 2023 | K29: Franzini | L29: 45107 | N29: YES | O29: Completato | P29: 1127-BIOSYLVA--BIOSYL I--2023
A30: 1130 | B30: IT00123COC00309 | C30: - | D30: BIPAN | F30: BIPAN | G30: CARICO SFIBRATORE | H30: ITALY | I30: ITALIA | J30: 2023 | K30: Fragale | L30: 45047 | N30: YES | P30: 1130-BIPAN--BIPAN-CARICO SFIBRATORE-2023
A31: 1130 | B31: IT00123COC00078 | C31: - | D31: BIPAN | F31: BIPAN | G31: N°2 COCLEE, MTR FORNITI DA CLIENTE | H31: ITALY | I31: ITALIA | J31: 2023 | K31: Fragale | L31: 45145 | N31: YES | P31: 1130-BIPAN--BIPAN-N°2 COCLEE, MTR FORNITI DA CLIENTE-2023
A32: IT0012025TRT00101 | B32: IT00125COC00055 | C32: - | D32: BIPAN | F32: BIPAN | H32: ITALY | I32: ITALIA | J32: 2025 | K32: Fragale | L32: 45855 | N32: YES | P32: IT0012025TRT00101-BIPAN--BIPAN--2025
A33: 701 | B33: AS202 | C33: link | D33: BIPAN S.P.A | F33: NEW SILO FIBRA | H33: ITALY | J33: 2016 | N33: - | O33: Completato | P33: 701-BIPAN S.P.A--NEW SILO FIBRA--2016
A34: 727 | B34: AS747 | C34: link | D34: BIPAN S.P.A | F34: BIPAN S.P.A | H34: ITALY | J34: 2016 | L34: 42724 | N34: YES | O34: Completato | P34: 727-BIPAN S.P.A--BIPAN S.P.A--2016
A35: IT0012025TRT00140 | B35: TM9124 BOMBAY DYEING FHS & AHS - R2-15-04-2025. | C35: - | D35: BOMBAY DYEING CO. LTD | F35: PATALGANGA MAHARASHTRA | G35: FHS + AHS | H35: INDIA | I35: INDIA | J35: 2025 | K35: Pannunzio | L35: 45976 | M35: FHS: 1 TKK19; 1COC; 1 TN650 ASH: 1 ATC | N35: NO | O35: SCHEMES TO BE FINALIZED | P35: IT0012025TRT00140-BOMBAY DYEING CO. LTD--PATALGANGA MAHARASHTRA-FHS + AHS-2025
A36: 718 | B36: AS358 parte A | C36: link | D36: BORG | F36: NEW PB PLANT | H36: AUSTRALIA | J36: 2016 | K36: Longari | L36: 42853 | N36: YES | O36: Completato | P36: 718-BORG--NEW PB PLANT--2016
A37: 718 | B37: AS358 parte B | C37: link | D37: BORG | F37: NEW PB PLANT | H37: AUSTRALIA | J37: 2016 | K37: Longari | L37: 43018 | N37: YES | O37: Completato | P37: 718-BORG--NEW PB PLANT--2016
A38: 718 | B38: AT675 | C38: link | D38: BORG | F38: NEW PB PLANT | H38: AUSTRALIA | J38: 2016 | K38: Longari | L38: 43089 | N38: NOT REQUIRED | O38: Completato | P38: 718-BORG--NEW PB PLANT-2016
A39: 841 | B39: IT00118COC00390 | C39: link | D39: BORG | F39: NEW PB PLANT | G39: SERRANDE SOTTO TK | H39: AUSTRALIA | J39: 2018 | K39: Longari | L39: 43437 | N39: YES | O39: Completato | P39: 841-BORG--NEW PB PLANT-2018
A40: 894 | B40: IT00119COC00561 | C40: link | D40: BORG | F40: NEW PB PLANT | G40: MOVING FLOOR SYSTEM | H40: AUSTRALIA | J40: 2019 | K40: Fragale | L40: 43803 | N40: YES | P40: 894-BORG--NEW PB PLANT-2019
...

Sheet ML
A1: MOTOR LIST | T1: IMPORTANT NOTES | AL1: TRASMEC s.r.l. Via Bergamo, 2/a 26011 Casalbuttano (CR) Technical dept.
A2: Customer | C2: =IFERROR(IF(VLOOKUP(TRIM($B$6), Foglio1!$B$2:$I$1167, 3, FALSE) = 0, "", VLOOKUP(TRIM($B$6), Foglio1!$B$2:$I$1167, 3, FALSE)), "") -> SOBONO ENERGY | I2: Rev.N° | J2: 0 | K2: by | L2: F.F. | N2: date | O2: 45755 | Q2: Status | T2: IT IS STRONGLY RECOMMENDED TO USE SEW EURODRIVE FREQUENCY CONVERTER (INVERTER) MOVITRAC/MOVIDRIVE MODELS FOR THE GUARANTEED PERFORMANCES AND FLEXIBILITY OF TYPE: VECTOR FLUX CONTROLLER, OPEN LOOP, WITH A POWER OF 20% MORE THAN THE MOTOR INSTALLED POWER. IT IS NECESSARY THAT THE FREQUENCY CONVERTER (INVERTER) START THE MOTOR WITH THE 150% OF THE MAXIMUM RATED TORQUE FOR 10 SECONDS. AFTER THIS TIME THE INVERTER MUST INTERVENE TO STOP THE CONVEYOR WHEN IT REACHES THE MAXIMUM RATED TORQUE OF MOTOR AT THE INSTALLATION HERTZ. IN CASE OF MACHINE OPERATED WITH FREQUENCY CONVERTER OR SOFTSTART, FOLLOW THE INDICATION OF FILE "IM0007 EN".
A3: Final Customer | C3: =IFERROR(IF(VLOOKUP(TRIM($B$6), Foglio1!$B$2:$I$1167, 4, FALSE) = 0, "", VLOOKUP(TRIM($B$6), Foglio1!$B$2:$I$1167, 4, FALSE)), "") | I3: Rev.N° | J3: 1 | K3: by | L3: F.F. | N3: date | O3: 45765
A4: Plant | C4: =IFERROR(IF(VLOOKUP(TRIM($B$6), Foglio1!$B$2:$I$1167, 5, FALSE) = 0, "", VLOOKUP(TRIM($B$6), Foglio1!$B$2:$I$1167, 5, FALSE)), "") -> Energy Plant | I4: Rev.N° | J4: 2 | K4: by | L4: F.F. | N4: date | O4: 45824 | Q4: RELEASED
A5: Location | C5: =IFERROR(IF(VLOOKUP(TRIM($B$6), Foglio1!$B$2:$I$1167, 7, FALSE) = 0, "", VLOOKUP(TRIM($B$6), Foglio1!$B$2:$I$1167, 7, FALSE)), "") -> SINGAPORE | I5: Rev.N° | J5: 3 | K5: by | L5: F.F. | N5: date | O5: 45855 | T5: IF 2 MOTORS ARE DRIVING THE SAME SHAFT AND DRIVED BY FREQUENCY CONVERTER, IT IS STRONGLY RECOMMENDED THE USE OF ONE FREQUENCY CONVERTER DRIVING BOTH MOTORS. FREQUENCY CONVERTER SHALL BE CHOOSEN ACCORDING TO THE RULE ABOVE, CONSIDERING THE RATED TORQUE EQUAL TO THE SUMM OF BOTH MOTORS.
A6: Order n° | B6: IT00125COC00050 | D6: Project N° | G6: =IFERROR(INDEX(Foglio1!A2:A1167, MATCH(TRIM($B$6), Foglio1!B2:B1167, 0)),"-") -> IT0012025TRT00044 | I6: Rev.N° | K6: by | N6: date | T6: TRASMEC SUPPLIES ALWAYS "TF" THERMAL PROTECTION. IT IS MANDATORY TO BE CONNECTED IN CASE OF FREQUENCY CONVERTER. IN CASE OF GEARMOTOR DRIVEN BY FREQUENCY CONVERTER AND NO FORCED COOLING FAN IS INSTALLED, FREQUENCY MUST NEVER BE SET LOWER THAN 40Hz
A8: ITEM NUMBER | B8: TRASMEC JOB N° | C8: LAYOUT POSITION | D8: QTY | E8: GEAR MOTOR BASIC DATA | W8: EQUIPMENTS | AG8: DENOMINATION | AH8: SUPPLIER | AI8: TF mandatory to be connected? | AJ8: Painting RAL (0=STD SEW RAL7031) | AK8: Atex (0=NO) | AL8: NOTE | AM8: INTERNAL USE
E9: Art. | F9: KW - Power supply | G9: rpm speed at installation Hz | H9: rpm speet at 50HZ | I9: type | J9: Nm - torque | K9: i - Reduction ratio | L9: fB Service factor | M9: Mounting position | N9: Efficiency (STD: IE3) | O9: V - operating voltage | P9: Cable connection (D = triangle; Y = STAR) | Q9: N° of poles | R9: Hz - Network Frequency | S9: A - Ampere at 100% | T9: IP - Motor protection | U9: Insulation class | V9: JB position | W9: Temperature protection | X9: Forced cooling fan (same tension of the motor) | Y9: RS | Z9: Brake (std: 400V 1Phase) | AA9: T=Torque arm G = Rubber buffers | AB9: Starter type | AC9: Working HZ MIN | AD9: Working HZ MAX | AE9: Strip heater (std: 230V 1Phase) | AF9: oil type | AM9: Symplified 3D model code
A11: MR004777 | B11: BE0805C | C11: TM F00 | D11: 1 | E11: =IF($A11>0,VLOOKUP($A11,[1]Foglio1!$A$1:$IV$65536,2,FALSE)," ") -> MR | F11: =IF($A11>0,VLOOKUP($A11,[1]Foglio1!$A$1:$IV$65536,3,FALSE)," ") -> 0.55 | G11: =H11*R11/50 -> 3.9 | H11: =IF($A11>0,VLOOKUP($A11,[1]Foglio1!$A$1:$IV$65536,4,FALSE)," ") -> 3.9 | I11: =IF($A11>0,VLOOKUP($A11,[1]Foglio1!$A$1:$IV$65536,5,FALSE)," ") -> KA77R37 | J11: =IF($A11>0,VLOOKUP($A11,[1]Foglio1!$A$1:$IV$65536,6,FALSE)," ") -> 1210 | K11: =IF($A11>0,VLOOKUP($A11,[1]Foglio1!$A$1:$IV$65536,7,FALSE)," ") -> 367 | L11: =IF($A11>0,VLOOKUP($A11,[1]Foglio1!$A$1:$IV$65536,8,FALSE)," ") -> 1.25 | M11: =IF($A11>0,VLOOKUP($A11,[1]Foglio1!$A$1:$IV$65536,9,FALSE)," ") -> M3B | N11: =IF($A11>0,VLOOKUP($A11,[1]Foglio1!$A$1:$IV$65536,10,FALSE)," ") -> IE3 | O11: =IF($A11>0,VLOOKUP($A11,[1]Foglio1!$A$1:$IV$65536,11,FALSE)," ") -> 230/400 | R11: =IF($A11>0,VLOOKUP($A11,[1]Foglio1!$A$1:$IV$65536,12,FALSE)," ") -> 50 | S11: =IF($A11>0,VLOOKUP($A11,[1]Foglio1!$A$1:$IV$65536,13,FALSE)," ") -> 2,25/1,29 | T11: =IF($A11>0,VLOOKUP($A11,[1]Foglio1!$A$1:$IV$65536,14,FALSE)," ") -> 55 | U11: =IF($A11>0,VLOOKUP($A11,[1]Foglio1!$A$1:$IV$65536,15,FALSE)," ") -> 155(F) | V11: =IF($A11>0,VLOOKUP($A11,[1]Foglio1!$A$1:$IV$65536,16,FALSE)," ") -> 0° | W11: =IF($A11>0,VLOOKUP($A11,[1]Foglio1!$A$1:$IV$65536,17,FALSE)," ") -> TF | X11: =IF($A11>0,IF(VLOOKUP($A11,[1]Foglio1!$A$1:$IV$65536,18,FALSE)<>"-","YES","NO")," ") -> NO | Y11: =IF($A11>0,VLOOKUP($A11,[1]Foglio1!$A$1:$IV$65536,19,FALSE)," ") -> - | Z11: =IF($A11>0,VLOOKUP($A11,[1]Foglio1!$A$1:$IV$65536,20,FALSE)," ") -> BEHF | AA11: =IF($A11>0,VLOOKUP($A11,[1]Foglio1!$A$1:$IV$65536,21,FALSE)," ") -> T | AB11: =IF($A11>0,VLOOKUP($A11,[1]Foglio1!$A$1:$IV$65536,22,FALSE)," ") -> D+R | AE11: =IF($A11>0,VLOOKUP($A11,[1]Foglio1!$A$1:$IV$65536,23,FALSE)," ") -> - | AF11: =IF($A11>0,VLOOKUP($A11,[1]Foglio1!$A$1:$IV$65536,24,FALSE)," ") -> CLP 220 (-15/+40°C) | AG11: =IF($A11>0,VLOOKUP($A11,[1]Foglio1!$A$1:$IV$65536,25,FALSE)," ") -> KA77R37/T DRN80MK4 /BEHF /TF | AH11: =IF($A11>0,VLOOKUP($A11,[1]Foglio1!$A$1:$IV$65536,26,FALSE)," ") -> SEW | AI11: =IF(X11="YES", "YES",IF(A11="","-","NO")) -> NO | AJ11: =IF($A11>0,VLOOKUP($A11,[1]Foglio1!$A$1:$IV$65536,27,FALSE)," ") -> 0 | AK11: =IF($A11>0,VLOOKUP($A11,[1]Foglio1!$A$1:$IV$65536,28,FALSE)," ") -> - | AL11: =IF($A11>0,VLOOKUP($A11,[1]Foglio1!$A$1:$IV$65536,31,FALSE)," ") -> 0 | AM11: =IF($A11>0,VLOOKUP($A11,[1]Foglio1!$A$1:$IV$65536,34,FALSE)," ") -> KA77R37T-DRN80MK4B0-X | AN11: TRM CHN
A13: MR005244 | B13: BE0806C | C13: TM F01 | D13: 1 | E13: =IF($A13>0,VLOOKUP($A13,[1]Foglio1!$A$1:$IV$65536,2,FALSE)," ") -> MR | F13: =IF($A13>0,VLOOKUP($A13,[1]Foglio1!$A$1:$IV$65536,3,FALSE)," ") -> 11 | G13: =H13*R13/50 -> 56 | H13: =IF($A13>0,VLOOKUP($A13,[1]Foglio1!$A$1:$IV$65536,4,FALSE)," ") -> 56 | I13: =IF($A13>0,VLOOKUP($A13,[1]Foglio1!$A$1:$IV$65536,5,FALSE)," ") -> FH87 | J13: =IF($A13>0,VLOOKUP($A13,[1]Foglio1!$A$1:$IV$65536,6,FALSE)," ") -> 1880 | K13: =IF($A13>0,VLOOKUP($A13,[1]Foglio1!$A$1:$IV$65536,7,FALSE)," ") -> 26.5 | L13: =IF($A13>0,VLOOKUP($A13,[1]Foglio1!$A$1:$IV$65536,8,FALSE)," ") -> 1.6 | M13: =IF($A13>0,VLOOKUP($A13,[1]Foglio1!$A$1:$IV$65536,9,FALSE)," ") -> From M1 to M2 - 5° | N13: =IF($A13>0,VLOOKUP($A13,[1]Foglio1!$A$1:$IV$65536,10,FALSE)," ") -> IE3 | O13: =IF($A13>0,VLOOKUP($A13,[1]Foglio1!$A$1:$IV$65536,11,FALSE)," ") -> 230/400 | R13: =IF($A13>0,VLOOKUP($A13,[1]Foglio1!$A$1:$IV$65536,12,FALSE)," ") -> 50 | S13: =IF($A13>0,VLOOKUP($A13,[1]Foglio1!$A$1:$IV$65536,13,FALSE)," ") -> 36,5/21 | T13: =IF($A13>0,VLOOKUP($A13,[1]Foglio1!$A$1:$IV$65536,14,FALSE)," ") -> 55 | U13: =IF($A13>0,VLOOKUP($A13,[1]Foglio1!$A$1:$IV$65536,15,FALSE)," ") -> 155(F) | V13: =IF($A13>0,VLOOKUP($A13,[1]Foglio1!$A$1:$IV$65536,16,FALSE)," ") -> 270° | W13: =IF($A13>0,VLOOKUP($A13,[1]Foglio1!$A$1:$IV$65536,17,FALSE)," ") -> TF | X13: =IF($A13>0,IF(VLOOKUP($A13,[1]Foglio1!$A$1:$IV$65536,18,FALSE)<>"-","YES","NO")," ") -> YES | Y13: =IF($A13>0,VLOOKUP($A13,[1]Foglio1!$A$1:$IV$65536,19,FALSE)," ") -> - | Z13: =IF($A13>0,VLOOKUP($A13,[1]Foglio1!$A$1:$IV$65536,20,FALSE)," ") -> - | AA13: =IF($A13>0,VLOOKUP($A13,[1]Foglio1!$A$1:$IV$65536,21,FALSE)," ") -> G | AB13: =IF($A13>0,VLOOKUP($A13,[1]Foglio1!$A$1:$IV$65536,22,FALSE)," ") -> FC | AE13: =IF($A13>0,VLOOKUP($A13,[1]Foglio1!$A$1:$IV$65536,23,FALSE)," ") -> - | AF13: =IF($A13>0,VLOOKUP($A13,[1]Foglio1!$A$1:$IV$65536,24,FALSE)," ") -> CLP 220 (-15/+40°C) | AG13: =IF($A13>0,VLOOKUP($A13,[1]Foglio1!$A$1:$IV$65536,25,FALSE)," ") -> FH87/G DRN160M4 /TF/V | AH13: =IF($A13>0,VLOOKUP($A13,[1]Foglio1!$A$1:$IV$65536,26,FALSE)," ") -> SEW | AI13: =IF(X13="YES", "YES",IF(A13="","-","NO")) -> YES | AJ13: =IF($A13>0,VLOOKUP($A13,[1]Foglio1!$A$1:$IV$65536,27,FALSE)," ") -> 0 | AK13: =IF($A13>0,VLOOKUP($A13,[1]Foglio1!$A$1:$IV$65536,28,FALSE)," ") -> - | AL13: =IF($A13>0,VLOOKUP($A13,[1]Foglio1!$A$1:$IV$65536,31,FALSE)," ") -> 0 | AM13: =IF($A13>0,VLOOKUP($A13,[1]Foglio1!$A$1:$IV$65536,34,FALSE)," ") -> FH87G-DRN160M4270-X# | AN13: TRM ITY
A14: Servofan | D14: 1 | F14: 0,084 | O14: 230/400 | R14: 50 | S14: 0,43/0,25 | T14: 66 | AB14: D | AL14: Also available monophase 230V 0,34A
A16: MR005245 | B16: BE0807C | C16: TM F02 | D16: 1 | E16: =IF($A16>0,VLOOKUP($A16,[1]Foglio1!$A$1:$IV$65536,2,FALSE)," ") -> MR | F16: =IF($A16>0,VLOOKUP($A16,[1]Foglio1!$A$1:$IV$65536,3,FALSE)," ") -> 18.5 | G16: =H16*R16/50 -> 16 | H16: =IF($A16>0,VLOOKUP($A16,[1]Foglio1!$A$1:$IV$65536,4,FALSE)," ") -> 16 | I16: =IF($A16>0,VLOOKUP($A16,[1]Foglio1!$A$1:$IV$65536,5,FALSE)," ") -> KH127 | J16: =IF($A16>0,VLOOKUP($A16,[1]Foglio1!$A$1:$IV$65536,6,FALSE)," ") -> 11300 | K16: =IF($A16>0,VLOOKUP($A16,[1]Foglio1!$A$1:$IV$65536,7,FALSE)," ") -> 94.6 | L16: =IF($A16>0,VLOOKUP($A16,[1]Foglio1!$A$1:$IV$65536,8,FALSE)," ") -> 1.15 | M16: =IF($A16>0,VLOOKUP($A16,[1]Foglio1!$A$1:$IV$65536,9,FALSE)," ") -> From M1A to M4A - 85° | N16: =IF($A16>0,VLOOKUP($A16,[1]Foglio1!$A$1:$IV$65536,10,FALSE)," ") -> IE3 | O16: =IF($A16>0,VLOOKUP($A16,[1]Foglio1!$A$1:$IV$65536,11,FALSE)," ") -> 400/690 | R16: =IF($A16>0,VLOOKUP($A16,[1]Foglio1!$A$1:$IV$65536,12,FALSE)," ") -> 50 | S16: =IF($A16>0,VLOOKUP($A16,[1]Foglio1!$A$1:$IV$65536,13,FALSE)," ") -> 33,5/19,3 | T16: =IF($A16>0,VLOOKUP($A16,[1]Foglio1!$A$1:$IV$65536,14,FALSE)," ") -> 55 | U16: =IF($A16>0,VLOOKUP($A16,[1]Foglio1!$A$1:$IV$65536,15,FALSE)," ") -> 155(F) | V16: =IF($A16>0,VLOOKUP($A16,[1]Foglio1!$A$1:$IV$65536,16,FALSE)," ") -> 270° | W16: =IF($A16>0,VLOOKUP($A16,[1]Foglio1!$A$1:$IV$65536,17,FALSE)," ") -> TF | X16: =IF($A16>0,IF(VLOOKUP($A16,[1]Foglio1!$A$1:$IV$65536,18,FALSE)<>"-","YES","NO")," ") -> NO | Y16: =IF($A16>0,VLOOKUP($A16,[1]Foglio1!$A$1:$IV$65536,19,FALSE)," ") -> - | Z16: =IF($A16>0,VLOOKUP($A16,[1]Foglio1!$A$1:$IV$65536,20,FALSE)," ") -> - | AA16: =IF($A16>0,VLOOKUP($A16,[1]Foglio1!$A$1:$IV$65536,21,FALSE)," ") -> - | AB16: =IF($A16>0,VLOOKUP($A16,[1]Foglio1!$A$1:$IV$65536,22,FALSE)," ") -> SS | AE16: =IF($A16>0,VLOOKUP($A16,[1]Foglio1!$A$1:$IV$65536,23,FALSE)," ") -> - | AF16: =IF($A16>0,VLOOKUP($A16,[1]Foglio1!$A$1:$IV$65536,24,FALSE)," ") -> CLP 220 (-15/+40°C) | AG16: =IF($A16>0,VLOOKUP($A16,[1]Foglio1!$A$1:$IV$65536,25,FALSE)," ") -> KH127EDRN180M4 /TF | AH16: =IF($A16>0,VLOOKUP($A16,[1]Foglio1!$A$1:$IV$65536,26,FALSE)," ") -> SEW | AI16: =IF(X16="YES", "YES",IF(A16="","-","NO")) -> NO | AJ16: =IF($A16>0,VLOOKUP($A16,[1]Foglio1!$A$1:$IV$65536,27,FALSE)," ") -> 0 | AK16: =IF($A16>0,VLOOKUP($A16,[1]Foglio1!$A$1:$IV$65536,28,FALSE)," ") -> ATEX22 | AL16: =IF($A16>0,VLOOKUP($A16,[1]Foglio1!$A$1:$IV$65536,31,FALSE)," ") -> 0 | AM16: =IF($A16>0,VLOOKUP($A16,[1]Foglio1!$A$1:$IV$65536,34,FALSE)," ") -> KH127-EDRN180M4A270-X | AN16: TRM CHN
A17: MR005246 | B17: BE0807C | C17: TM F02 | D17: 1 | E17: =IF($A17>0,VLOOKUP($A17,[1]Foglio1!$A$1:$IV$65536,2,FALSE)," ") -> MR | F17: =IF($A17>0,VLOOKUP($A17,[1]Foglio1!$A$1:$IV$65536,3,FALSE)," ") -> 18.5 | G17: =H17*R17/50 -> 16 | H17: =IF($A17>0,VLOOKUP($A17,[1]Foglio1!$A$1:$IV$65536,4,FALSE)," ") -> 16 | I17: =IF($A17>0,VLOOKUP($A17,[1]Foglio1!$A$1:$IV$65536,5,FALSE)," ") -> KH127 | J17: =IF($A17>0,VLOOKUP($A17,[1]Foglio1!$A$1:$IV$65536,6,FALSE)," ") -> 11300 | K17: =IF($A17>0,VLOOKUP($A17,[1]Foglio1!$A$1:$IV$65536,7,FALSE)," ") -> 94.6 | L17: =IF($A17>0,VLOOKUP($A17,[1]Foglio1!$A$1:$IV$65536,8,FALSE)," ") -> 1.15 | M17: =IF($A17>0,VLOOKUP($A17,[1]Foglio1!$A$1:$IV$65536,9,FALSE)," ") -> From M1B to M4B - 85° | N17: =IF($A17>0,VLOOKUP($A17,[1]Foglio1!$A$1:$IV$65536,10,FALSE)," ") -> IE3 | O17: =IF($A17>0,VLOOKUP($A17,[1]Foglio1!$A$1:$IV$65536,11,FALSE)," ") -> 400/690 | R17: =IF($A17>0,VLOOKUP($A17,[1]Foglio1!$A$1:$IV$65536,12,FALSE)," ") -> 50 | S17: =IF($A17>0,VLOOKUP($A17,[1]Foglio1!$A$1:$IV$65536,13,FALSE)," ") -> 33,5/19,3 | T17: =IF($A17>0,VLOOKUP($A17,[1]Foglio1!$A$1:$IV$65536,14,FALSE)," ") -> 55 | U17: =IF($A17>0,VLOOKUP($A17,[1]Foglio1!$A$1:$IV$65536,15,FALSE)," ") -> 155(F) | V17: =IF($A17>0,VLOOKUP($A17,[1]Foglio1!$A$1:$IV$65536,16,FALSE)," ") -> 270° | W17: =IF($A17>0,VLOOKUP($A17,[1]Foglio1!$A$1:$IV$65536,17,FALSE)," ") -> TF | X17: =IF($A17>0,IF(VLOOKUP($A17,[1]Foglio1!$A$1:$IV$65536,18,FALSE)<>"-","YES","NO")," ") -> NO | Y17: =IF($A17>0,VLOOKUP($A17,[1]Foglio1!$A$1:$IV$65536,19,FALSE)," ") -> - | Z17: =IF($A17>0,VLOOKUP($A17,[1]Foglio1!$A$1:$IV$65536,20,FALSE)," ") -> - | AA17: =IF($A17>0,VLOOKUP($A17,[1]Foglio1!$A$1:$IV$65536,21,FALSE)," ") -> - | AB17: =IF($A17>0,VLOOKUP($A17,[1]Foglio1!$A$1:$IV$65536,22,FALSE)," ") -> SS | AE17: =IF($A17>0,VLOOKUP($A17,[1]Foglio1!$A$1:$IV$65536,23,FALSE)," ") -> - | AF17: =IF($A17>0,VLOOKUP($A17,[1]Foglio1!$A$1:$IV$65536,24,FALSE)," ") -> CLP 220 (-15/+40°C) | AG17: =IF($A17>0,VLOOKUP($A17,[1]Foglio1!$A$1:$IV$65536,25,FALSE)," ") -> KH127EDRN180M4 /TF | AH17: =IF($A17>0,VLOOKUP($A17,[1]Foglio1!$A$1:$IV$65536,26,FALSE)," ") -> SEW | AI17: =IF(X17="YES", "YES",IF(A17="","-","NO")) -> NO | AJ17: =IF($A17>0,VLOOKUP($A17,[1]Foglio1!$A$1:$IV$65536,27,FALSE)," ") -> 0 | AK17: =IF($A17>0,VLOOKUP($A17,[1]Foglio1!$A$1:$IV$65536,28,FALSE)," ") -> ATEX22 | AL17: =IF($A17>0,VLOOKUP($A17,[1]Foglio1!$A$1:$IV$65536,31,FALSE)," ") -> 0 | AM17: =IF($A17>0,VLOOKUP($A17,[1]Foglio1!$A$1:$IV$65536,34,FALSE)," ") -> KH127-EDRN180M4B270-X | AN17: TRM CHN
A19: MR005247 | B19: BE0808C | C19: TM F02.1 | D19: 1 | E19: =IF($A19>0,VLOOKUP($A19,[1]Foglio1!$A$1:$IV$65536,2,FALSE)," ") -> MR | F19: =IF($A19>0,VLOOKUP($A19,[1]Foglio1!$A$1:$IV$65536,3,FALSE)," ") -> 1.5 | G19: =H19*R19/50 -> 22 | H19: =IF($A19>0,VLOOKUP($A19,[1]Foglio1!$A$1:$IV$65536,4,FALSE)," ") -> 22 | I19: =IF($A19>0,VLOOKUP($A19,[1]Foglio1!$A$1:$IV$65536,5,FALSE)," ") -> FA67 | J19: =IF($A19>0,VLOOKUP($A19,[1]Foglio1!$A$1:$IV$65536,6,FALSE)," ") -> 665 | K19: =IF($A19>0,VLOOKUP($A19,[1]Foglio1!$A$1:$IV$65536,7,FALSE)," ") -> 67,65 | L19: =IF($A19>0,VLOOKUP($A19,[1]Foglio1!$A$1:$IV$65536,8,FALSE)," ") -> 1,15 | M19: =IF($A19>0,VLOOKUP($A19,[1]Foglio1!$A$1:$IV$65536,9,FALSE)," ") -> From M5 to M3 - 5° | N19: =IF($A19>0,VLOOKUP($A19,[1]Foglio1!$A$1:$IV$65536,10,FALSE)," ") -> IE3 | O19: =IF($A19>0,VLOOKUP($A19,[1]Foglio1!$A$1:$IV$65536,11,FALSE)," ") -> 230/400 | R19: =IF($A19>0,VLOOKUP($A19,[1]Foglio1!$A$1:$IV$65536,12,FALSE)," ") -> 50 | S19: =IF($A19>0,VLOOKUP($A19,[1]Foglio1!$A$1:$IV$65536,13,FALSE)," ") -> 6,1/3,5 | T19: =IF($A19>0,VLOOKUP($A19,[1]Foglio1!$A$1:$IV$65536,14,FALSE)," ") -> 55 | U19: =IF($A19>0,VLOOKUP($A19,[1]Foglio1!$A$1:$IV$65536,15,FALSE)," ") -> 155(F) | V19: =IF($A19>0,VLOOKUP($A19,[1]Foglio1!$A$1:$IV$65536,16,FALSE)," ") -> 180° | W19: =IF($A19>0,VLOOKUP($A19,[1]Foglio1!$A$1:$IV$65536,17,FALSE)," ") -> TF | X19: =IF($A19>0,IF(VLOOKUP($A19,[1]Foglio1!$A$1:$IV$65536,18,FALSE)<>"-","YES","NO")," ") -> NO | Y19: =IF($A19>0,VLOOKUP($A19,[1]Foglio1!$A$1:$IV$65536,19,FALSE)," ") -> - | Z19: =IF($A19>0,VLOOKUP($A19,[1]Foglio1!$A$1:$IV$65536,20,FALSE)," ") -> BEHF | AA19: =IF($A19>0,VLOOKUP($A19,[1]Foglio1!$A$1:$IV$65536,21,FALSE)," ") -> G | AB19: =IF($A19>0,VLOOKUP($A19,[1]Foglio1!$A$1:$IV$65536,22,FALSE)," ") -> D+R | AE19: =IF($A19>0,VLOOKUP($A19,[1]Foglio1!$A$1:$IV$65536,23,FALSE)," ") -> - | AF19: =IF($A19>0,VLOOKUP($A19,[1]Foglio1!$A$1:$IV$65536,24,FALSE)," ") -> CLP 220 (-15/+40°C) | AG19: =IF($A19>0,VLOOKUP($A19,[1]Foglio1!$A$1:$IV$65536,25,FALSE)," ") -> FA67/G EDRN90L4 /BEHF /TF | AH19: =IF($A19>0,VLOOKUP($A19,[1]Foglio1!$A$1:$IV$65536,26,FALSE)," ") -> SEW | AI19: =IF(X19="YES", "YES",IF(A19="","-","NO")) -> NO | AJ19: =IF($A19>0,VLOOKUP($A19,[1]Foglio1!$A$1:$IV$65536,27,FALSE)," ") -> 0 | AK19: =IF($A19>0,VLOOKUP($A19,[1]Foglio1!$A$1:$IV$65536,28,FALSE)," ") -> ATEX22 | AL19: =IF($A19>0,VLOOKUP($A19,[1]Foglio1!$A$1:$IV$65536,31,FALSE)," ") -> Rectifier for brake in the terminal box | AM19: =IF($A19>0,VLOOKUP($A19,[1]Foglio1!$A$1:$IV$65536,34,FALSE)," ") -> FA67G-EDRN90L4180-X | AN19: TRM CHN
A21: MR005248 | B21: BE0809C | C21: TM F03 | D21: 1 | E21: =IF($A21>0,VLOOKUP($A21,[1]Foglio1!$A$1:$IV$65536,2,FALSE)," ") -> MR | F21: =IF($A21>0,VLOOKUP($A21,[1]Foglio1!$A$1:$IV$65536,3,FALSE)," ") -> 5.5 | G21: =H21*R21/50 -> 57 | H21: =IF($A21>0,VLOOKUP($A21,[1]Foglio1!$A$1:$IV$65536,4,FALSE)," ") -> 57 | I21: =IF($A21>0,VLOOKUP($A21,[1]Foglio1!$A$1:$IV$65536,5,FALSE)," ") -> KH77 | J21: =IF($A21>0,VLOOKUP($A21,[1]Foglio1!$A$1:$IV$65536,6,FALSE)," ") -> 920 | K21: =IF($A21>0,VLOOKUP($A21,[1]Foglio1!$A$1:$IV$65536,7,FALSE)," ") -> 25.62 | L21: =IF($A21>0,VLOOKUP($A21,[1]Foglio1!$A$1:$IV$65536,8,FALSE)," ") -> 1.7 | M21: =IF($A21>0,VLOOKUP($A21,[1]Foglio1!$A$1:$IV$65536,9,FALSE)," ") -> From M1A to M4A -80° | N21: =IF($A21>0,VLOOKUP($A21,[1]Foglio1!$A$1:$IV$65536,10,FALSE)," ") -> IE3 | O21: =IF($A21>0,VLOOKUP($A21,[1]Foglio1!$A$1:$IV$65536,11,FALSE)," ") -> 230/400 | R21: =IF($A21>0,VLOOKUP($A21,[1]Foglio1!$A$1:$IV$65536,12,FALSE)," ") -> 50 | S21: =IF($A21>0,VLOOKUP($A21,[1]Foglio1!$A$1:$IV$65536,13,FALSE)," ") -> 10,5/6,10 | T21: =IF($A21>0,VLOOKUP($A21,[1]Foglio1!$A$1:$IV$65536,14,FALSE)," ") -> 55 | U21: =IF($A21>0,VLOOKUP($A21,[1]Foglio1!$A$1:$IV$65536,15,FALSE)," ") -> 155(F) | V21: =IF($A21>0,VLOOKUP($A21,[1]Foglio1!$A$1:$IV$65536,16,FALSE)," ") -> 270° | W21: =IF($A21>0,VLOOKUP($A21,[1]Foglio1!$A$1:$IV$65536,17,FALSE)," ") -> TF | X21: =IF($A21>0,IF(VLOOKUP($A21,[1]Foglio1!$A$1:$IV$65536,18,FALSE)<>"-","YES","NO")," ") -> NO | Y21: =IF($A21>0,VLOOKUP($A21,[1]Foglio1!$A$1:$IV$65536,19,FALSE)," ") -> - | Z21: =IF($A21>0,VLOOKUP($A21,[1]Foglio1!$A$1:$IV$65536,20,FALSE)," ") -> - | AA21: =IF($A21>0,VLOOKUP($A21,[1]Foglio1!$A$1:$IV$65536,21,FALSE)," ") -> T | AB21: =IF($A21>0,VLOOKUP($A21,[1]Foglio1!$A$1:$IV$65536,22,FALSE)," ") -> SS+R | AE21: =IF($A21>0,VLOOKUP($A21,[1]Foglio1!$A$1:$IV$65536,23,FALSE)," ") -> - | AF21: =IF($A21>0,VLOOKUP($A21,[1]Foglio1!$A$1:$IV$65536,24,FALSE)," ") -> CLP 220 (-15/+40°C) | AG21: =IF($A21>0,VLOOKUP($A21,[1]Foglio1!$A$1:$IV$65536,25,FALSE)," ") -> KH77/T EDRN132S4 /TF | AH21: =IF($A21>0,VLOOKUP($A21,[1]Foglio1!$A$1:$IV$65536,26,FALSE)," ") -> SEW | AI21: =IF(X21="YES", "YES",IF(A21="","-","NO")) -> NO | AJ21: =IF($A21>0,VLOOKUP($A21,[1]Foglio1!$A$1:$IV$65536,27,FALSE)," ") -> 0 | AK21: =IF($A21>0,VLOOKUP($A21,[1]Foglio1!$A$1:$IV$65536,28,FALSE)," ") -> ATEX22 | AL21: =IF($A21>0,VLOOKUP($A21,[1]Foglio1!$A$1:$IV$65536,31,FALSE)," ") -> 0 | AM21: =IF($A21>0,VLOOKUP($A21,[1]Foglio1!$A$1:$IV$65536,34,FALSE)," ") -> KH77T-EDRN132S4A270-X | AN21: TRM CHN
A22: MR005249 | B22: BE0809C | C22: TM F03 | D22: 1 | E22: =IF($A22>0,VLOOKUP($A22,[1]Foglio1!$A$1:$IV$65536,2,FALSE)," ") -> MR | F22: =IF($A22>0,VLOOKUP($A22,[1]Foglio1!$A$1:$IV$65536,3,FALSE)," ") -> 5.5 | G22: =H22*R22/50 -> 57 | H22: =IF($A22>0,VLOOKUP($A22,[1]Foglio1!$A$1:$IV$65536,4,FALSE)," ") -> 57 | I22: =IF($A22>0,VLOOKUP($A22,[1]Foglio1!$A$1:$IV$65536,5,FALSE)," ") -> KH77 | J22: =IF($A22>0,VLOOKUP($A22,[1]Foglio1!$A$1:$IV$65536,6,FALSE)," ") -> 920 | K22: =IF($A22>0,VLOOKUP($A22,[1]Foglio1!$A$1:$IV$65536,7,FALSE)," ") -> 25.62 | L22: =IF($A22>0,VLOOKUP($A22,[1]Foglio1!$A$1:$IV$65536,8,FALSE)," ") -> 1.7 | M22: =IF($A22>0,VLOOKUP($A22,[1]Foglio1!$A$1:$IV$65536,9,FALSE)," ") -> From M3B to M4B -80° | N22: =IF($A22>0,VLOOKUP($A22,[1]Foglio1!$A$1:$IV$65536,10,FALSE)," ") -> IE3 | O22: =IF($A22>0,VLOOKUP($A22,[1]Foglio1!$A$1:$IV$65536,11,FALSE)," ") -> 230/400 | R22: =IF($A22>0,VLOOKUP($A22,[1]Foglio1!$A$1:$IV$65536,12,FALSE)," ") -> 50 | S22: =IF($A22>0,VLOOKUP($A22,[1]Foglio1!$A$1:$IV$65536,13,FALSE)," ") -> 10,5/6,10 | T22: =IF($A22>0,VLOOKUP($A22,[1]Foglio1!$A$1:$IV$65536,14,FALSE)," ") -> 55 | U22: =IF($A22>0,VLOOKUP($A22,[1]Foglio1!$A$1:$IV$65536,15,FALSE)," ") -> 155(F) | V22: =IF($A22>0,VLOOKUP($A22,[1]Foglio1!$A$1:$IV$65536,16,FALSE)," ") -> 270° | W22: =IF($A22>0,VLOOKUP($A22,[1]Foglio1!$A$1:$IV$65536,17,FALSE)," ") -> TF | X22: =IF($A22>0,IF(VLOOKUP($A22,[1]Foglio1!$A$1:$IV$65536,18,FALSE)<>"-","YES","NO")," ") -> NO | Y22: =IF($A22>0,VLOOKUP($A22,[1]Foglio1!$A$1:$IV$65536,19,FALSE)," ") -> - | Z22: =IF($A22>0,VLOOKUP($A22,[1]Foglio1!$A$1:$IV$65536,20,FALSE)," ") -> - | AA22: =IF($A22>0,VLOOKUP($A22,[1]Foglio1!$A$1:$IV$65536,21,FALSE)," ") -> T | AB22: =IF($A22>0,VLOOKUP($A22,[1]Foglio1!$A$1:$IV$65536,22,FALSE)," ") -> SS+R | AE22: =IF($A22>0,VLOOKUP($A22,[1]Foglio1!$A$1:$IV$65536,23,FALSE)," ") -> - | AF22: =IF($A22>0,VLOOKUP($A22,[1]Foglio1!$A$1:$IV$65536,24,FALSE)," ") -> CLP 220 (-15/+40°C) | AG22: =IF($A22>0,VLOOKUP($A22,[1]Foglio1!$A$1:$IV$65536,25,FALSE)," ") -> KH77/T EDRN132S4 /TF | AH22: =IF($A22>0,VLOOKUP($A22,[1]Foglio1!$A$1:$IV$65536,26,FALSE)," ") -> SEW | AI22: =IF(X22="YES", "YES",IF(A22="","-","NO")) -> NO | AJ22: =IF($A22>0,VLOOKUP($A22,[1]Foglio1!$A$1:$IV$65536,27,FALSE)," ") -> 0 | AK22: =IF($A22>0,VLOOKUP($A22,[1]Foglio1!$A$1:$IV$65536,28,FALSE)," ") -> ATEX22 | AL22: =IF($A22>0,VLOOKUP($A22,[1]Foglio1!$A$1:$IV$65536,31,FALSE)," ") -> 0 | AM22: =IF($A22>0,VLOOKUP($A22,[1]Foglio1!$A$1:$IV$65536,34,FALSE)," ") -> KH77T-EDRN132S4B270-X | AN22: TRM CHN
A23: MR005250 | B23: BE0809C | C23: TM F03 | D23: 1 | E23: =IF($A23>0,VLOOKUP($A23,[1]Foglio1!$A$1:$IV$65536,2,FALSE)," ") -> MR | F23: =IF($A23>0,VLOOKUP($A23,[1]Foglio1!$A$1:$IV$65536,3,FALSE)," ") -> 0.75 | G23: =H23*R23/50 -> 162 | H23: =IF($A23>0,VLOOKUP($A23,[1]Foglio1!$A$1:$IV$65536,4,FALSE)," ") -> 162 | I23: =IF($A23>0,VLOOKUP($A23,[1]Foglio1!$A$1:$IV$65536,5,FALSE)," ") -> KA37 | J23: =IF($A23>0,VLOOKUP($A23,[1]Foglio1!$A$1:$IV$65536,6,FALSE)," ") -> 44 | K23: =IF($A23>0,VLOOKUP($A23,[1]Foglio1!$A$1:$IV$65536,7,FALSE)," ") -> 8.91 | L23: =IF($A23>0,VLOOKUP($A23,[1]Foglio1!$A$1:$IV$65536,8,FALSE)," ") -> 3.6 | M23: =IF($A23>0,VLOOKUP($A23,[1]Foglio1!$A$1:$IV$65536,9,FALSE)," ") -> From M3B to M2B -25° | N23: =IF($A23>0,VLOOKUP($A23,[1]Foglio1!$A$1:$IV$65536,10,FALSE)," ") -> IE3 | O23: =IF($A23>0,VLOOKUP($A23,[1]Foglio1!$A$1:$IV$65536,11,FALSE)," ") -> 230/400 | R23: =IF($A23>0,VLOOKUP($A23,[1]Foglio1!$A$1:$IV$65536,12,FALSE)," ") -> 50 | S23: =IF($A23>0,VLOOKUP($A23,[1]Foglio1!$A$1:$IV$65536,13,FALSE)," ") -> 3,05/1,75 | T23: =IF($A23>0,VLOOKUP($A23,[1]Foglio1!$A$1:$IV$65536,14,FALSE)," ") -> 55 | U23: =IF($A23>0,VLOOKUP($A23,[1]Foglio1!$A$1:$IV$65536,15,FALSE)," ") -> 155(F) | V23: =IF($A23>0,VLOOKUP($A23,[1]Foglio1!$A$1:$IV$65536,16,FALSE)," ") -> 270° | W23: =IF($A23>0,VLOOKUP($A23,[1]Foglio1!$A$1:$IV$65536,17,FALSE)," ") -> TF | X23: =IF($A23>0,IF(VLOOKUP($A23,[1]Foglio1!$A$1:$IV$65536,18,FALSE)<>"-","YES","NO")," ") -> NO | Y23: =IF($A23>0,VLOOKUP($A23,[1]Foglio1!$A$1:$IV$65536,19,FALSE)," ") -> - | Z23: =IF($A23>0,VLOOKUP($A23,[1]Foglio1!$A$1:$IV$65536,20,FALSE)," ") -> - | AA23: =IF($A23>0,VLOOKUP($A23,[1]Foglio1!$A$1:$IV$65536,21,FALSE)," ") -> T | AB23: =IF($A23>0,VLOOKUP($A23,[1]Foglio1!$A$1:$IV$65536,22,FALSE)," ") -> D | AE23: =IF($A23>0,VLOOKUP($A23,[1]Foglio1!$A$1:$IV$65536,23,FALSE)," ") -> - | AF23: =IF($A23>0,VLOOKUP($A23,[1]Foglio1!$A$1:$IV$65536,24,FALSE)," ") -> CLP 220 (-15/+40°C) | AG23: =IF($A23>0,VLOOKUP($A23,[1]Foglio1!$A$1:$IV$65536,25,FALSE)," ") -> KA37/T EDRN80M4 /TF | AH23: =IF($A23>0,VLOOKUP($A23,[1]Foglio1!$A$1:$IV$65536,26,FALSE)," ") -> SEW | AI23: =IF(X23="YES", "YES",IF(A23="","-","NO")) -> NO | AJ23: =IF($A23>0,VLOOKUP($A23,[1]Foglio1!$A$1:$IV$65536,27,FALSE)," ") -> 0 | AK23: =IF($A23>0,VLOOKUP($A23,[1]Foglio1!$A$1:$IV$65536,28,FALSE)," ") -> ATEX22 | AL23: =IF($A23>0,VLOOKUP($A23,[1]Foglio1!$A$1:$IV$65536,31,FALSE)," ") -> 0 | AM23: =IF($A23>0,VLOOKUP($A23,[1]Foglio1!$A$1:$IV$65536,34,FALSE)," ") -> KA37T-EDRN80M4B270-X | AN23: TRM CHN
A25: MR005241 | B25: BE0810C | C25: TM F04 | D25: 1 | E25: =IF($A25>0,VLOOKUP($A25,[1]Foglio1!$A$1:$IV$65536,2,FALSE)," ") -> MR | F25: =IF($A25>0,VLOOKUP($A25,[1]Foglio1!$A$1:$IV$65536,3,FALSE)," ") -> 0.55 | G25: =H25*R25/50 -> 3.9 | H25: =IF($A25>0,VLOOKUP($A25,[1]Foglio1!$A$1:$IV$65536,4,FALSE)," ") -> 3.9 | I25: =IF($A25>0,VLOOKUP($A25,[1]Foglio1!$A$1:$IV$65536,5,FALSE)," ") -> KA77R37 | J25: =IF($A25>0,VLOOKUP($A25,[1]Foglio1!$A$1:$IV$65536,6,FALSE)," ") -> 1210 | K25: =IF($A25>0,VLOOKUP($A25,[1]Foglio1!$A$1:$IV$65536,7,FALSE)," ") -> 367 | L25: =IF($A25>0,VLOOKUP($A25,[1]Foglio1!$A$1:$IV$65536,8,FALSE)," ") -> 1.25 | M25: =IF($A25>0,VLOOKUP($A25,[1]Foglio1!$A$1:$IV$65536,9,FALSE)," ") -> M3B | N25: =IF($A25>0,VLOOKUP($A25,[1]Foglio1!$A$1:$IV$65536,10,FALSE)," ") -> IE3 | O25: =IF($A25>0,VLOOKUP($A25,[1]Foglio1!$A$1:$IV$65536,11,FALSE)," ") -> 230/400 | R25: =IF($A25>0,VLOOKUP($A25,[1]Foglio1!$A$1:$IV$65536,12,FALSE)," ") -> 50 | S25: =IF($A25>0,VLOOKUP($A25,[1]Foglio1!$A$1:$IV$65536,13,FALSE)," ") -> 2,25/1,29 | T25: =IF($A25>0,VLOOKUP($A25,[1]Foglio1!$A$1:$IV$65536,14,FALSE)," ") -> 55 | U25: =IF($A25>0,VLOOKUP($A25,[1]Foglio1!$A$1:$IV$65536,15,FALSE)," ") -> 155(F) | V25: =IF($A25>0,VLOOKUP($A25,[1]Foglio1!$A$1:$IV$65536,16,FALSE)," ") -> 0° | W25: =IF($A25>0,VLOOKUP($A25,[1]Foglio1!$A$1:$IV$65536,17,FALSE)," ") -> TF | X25: =IF($A25>0,IF(VLOOKUP($A25,[1]Foglio1!$A$1:$IV$65536,18,FALSE)<>"-","YES","NO")," ") -> NO | Y25: =IF($A25>0,VLOOKUP($A25,[1]Foglio1!$A$1:$IV$65536,19,FALSE)," ") -> - | Z25: =IF($A25>0,VLOOKUP($A25,[1]Foglio1!$A$1:$IV$65536,20,FALSE)," ") -> BEHF | AA25: =IF($A25>0,VLOOKUP($A25,[1]Foglio1!$A$1:$IV$65536,21,FALSE)," ") -> T | AB25: =IF($A25>0,VLOOKUP($A25,[1]Foglio1!$A$1:$IV$65536,22,FALSE)," ") -> D+R | AE25: =IF($A25>0,VLOOKUP($A25,[1]Foglio1!$A$1:$IV$65536,23,FALSE)," ") -> - | AF25: =IF($A25>0,VLOOKUP($A25,[1]Foglio1!$A$1:$IV$65536,24,FALSE)," ") -> CLP 220 (-15/+40°C) | AG25: =IF($A25>0,VLOOKUP($A25,[1]Foglio1!$A$1:$IV$65536,25,FALSE)," ") -> KA77R37/T EDRE80S4 /BEHF /TF | AH25: =IF($A25>0,VLOOKUP($A25,[1]Foglio1!$A$1:$IV$65536,26,FALSE)," ") -> SEW | AI25: =IF(X25="YES", "YES",IF(A25="","-","NO")) -> NO | AJ25: =IF($A25>0,VLOOKUP($A25,[1]Foglio1!$A$1:$IV$65536,27,FALSE)," ") -> 0 | AK25: =IF($A25>0,VLOOKUP($A25,[1]Foglio1!$A$1:$IV$65536,28,FALSE)," ") -> ATEX22 | AL25: =IF($A25>0,VLOOKUP($A25,[1]Foglio1!$A$1:$IV$65536,31,FALSE)," ") -> 0 | AM25: =IF($A25>0,VLOOKUP($A25,[1]Foglio1!$A$1:$IV$65536,34,FALSE)," ") -> KA77R37T-EDRE80S4B0-X | AN25: TRM CHN
A27: MR005251 | B27: BE0811C | C27: TM F05 | D27: 1 | E27: =IF($A27>0,VLOOKUP($A27,[1]Foglio1!$A$1:$IV$65536,2,FALSE)," ") -> MR | F27: =IF($A27>0,VLOOKUP($A27,[1]Foglio1!$A$1:$IV$65536,3,FALSE)," ") -> 11 | G27: =H27*R27/50 -> 53 | H27: =IF($A27>0,VLOOKUP($A27,[1]Foglio1!$A$1:$IV$65536,4,FALSE)," ") -> 53 | I27: =IF($A27>0,VLOOKUP($A27,[1]Foglio1!$A$1:$IV$65536,5,FALSE)," ") -> R97 | J27: =IF($A27>0,VLOOKUP($A27,[1]Foglio1!$A$1:$IV$65536,6,FALSE)," ") -> 1960 | K27: =IF($A27>0,VLOOKUP($A27,[1]Foglio1!$A$1:$IV$65536,7,FALSE)," ") -> 27.58 | L27: =IF($A27>0,VLOOKUP($A27,[1]Foglio1!$A$1:$IV$65536,8,FALSE)," ") -> 1.35 | M27: =IF($A27>0,VLOOKUP($A27,[1]Foglio1!$A$1:$IV$65536,9,FALSE)," ") -> From M1 to M4 - 20° | N27: =IF($A27>0,VLOOKUP($A27,[1]Foglio1!$A$1:$IV$65536,10,FALSE)," ") -> IE3 | O27: =IF($A27>0,VLOOKUP($A27,[1]Foglio1!$A$1:$IV$65536,11,FALSE)," ") -> 400/690 | R27: =IF($A27>0,VLOOKUP($A27,[1]Foglio1!$A$1:$IV$65536,12,FALSE)," ") -> 50 | S27: =IF($A27>0,VLOOKUP($A27,[1]Foglio1!$A$1:$IV$65536,13,FALSE)," ") -> 21/12,2 | T27: =IF($A27>0,VLOOKUP($A27,[1]Foglio1!$A$1:$IV$65536,14,FALSE)," ") -> 55 | U27: =IF($A27>0,VLOOKUP($A27,[1]Foglio1!$A$1:$IV$65536,15,FALSE)," ") -> 155(F) | V27: =IF($A27>0,VLOOKUP($A27,[1]Foglio1!$A$1:$IV$65536,16,FALSE)," ") -> 270° | W27: =IF($A27>0,VLOOKUP($A27,[1]Foglio1!$A$1:$IV$65536,17,FALSE)," ") -> TF | X27: =IF($A27>0,IF(VLOOKUP($A27,[1]Foglio1!$A$1:$IV$65536,18,FALSE)<>"-","YES","NO")," ") -> NO | Y27: =IF($A27>0,VLOOKUP($A27,[1]Foglio1!$A$1:$IV$65536,19,FALSE)," ") -> - | Z27: =IF($A27>0,VLOOKUP($A27,[1]Foglio1!$A$1:$IV$65536,20,FALSE)," ") -> - | AA27: =IF($A27>0,VLOOKUP($A27,[1]Foglio1!$A$1:$IV$65536,21,FALSE)," ") -> - | AB27: =IF($A27>0,VLOOKUP($A27,[1]Foglio1!$A$1:$IV$65536,22,FALSE)," ") -> D | AE27: =IF($A27>0,VLOOKUP($A27,[1]Foglio1!$A$1:$IV$65536,23,FALSE)," ") -> - | AF27: =IF($A27>0,VLOOKUP($A27,[1]Foglio1!$A$1:$IV$65536,24,FALSE)," ") -> CLP 220 (-15/+40°C) | AG27: =IF($A27>0,VLOOKUP($A27,[1]Foglio1!$A$1:$IV$65536,25,FALSE)," ") -> R97EDRN160M4 /TF | AH27: =IF($A27>0,VLOOKUP($A27,[1]Foglio1!$A$1:$IV$65536,26,FALSE)," ") -> SEW | AI27: =IF(X27="YES", "YES",IF(A27="","-","NO")) -> NO | AJ27: =IF($A27>0,VLOOKUP($A27,[1]Foglio1!$A$1:$IV$65536,27,FALSE)," ") -> 0 | AK27: =IF($A27>0,VLOOKUP($A27,[1]Foglio1!$A$1:$IV$65536,28,FALSE)," ") -> ATEX22 | AL27: =IF($A27>0,VLOOKUP($A27,[1]Foglio1!$A$1:$IV$65536,31,FALSE)," ") -> 0 | AM27: =IF($A27>0,VLOOKUP($A27,[1]Foglio1!$A$1:$IV$65536,34,FALSE)," ") -> R97-EDRN160M4270-X | AN27: TRM CHN
A29: MR005253 | B29: BE0812C | C29: TM F06 | D29: 1 | E29: =IF($A29>0,VLOOKUP($A29,[1]Foglio1!$A$1:$IV$65536,2,FALSE)," ") -> MR | F29: =IF($A29>0,VLOOKUP($A29,[1]Foglio1!$A$1:$IV$65536,3,FALSE)," ") -> 7.5 | G29: =H29*R29/50 -> 59 | H29: =IF($A29>0,VLOOKUP($A29,[1]Foglio1!$A$1:$IV$65536,4,FALSE)," ") -> 59 | I29: =IF($A29>0,VLOOKUP($A29,[1]Foglio1!$A$1:$IV$65536,5,FALSE)," ") -> KH87 | J29: =IF($A29>0,VLOOKUP($A29,[1]Foglio1!$A$1:$IV$65536,6,FALSE)," ") -> 1210 | K29: =IF($A29>0,VLOOKUP($A29,[1]Foglio1!$A$1:$IV$65536,7,FALSE)," ") -> 24.95 | L29: =IF($A29>0,VLOOKUP($A29,[1]Foglio1!$A$1:$IV$65536,8,FALSE)," ") -> 2.1 | M29: =IF($A29>0,VLOOKUP($A29,[1]Foglio1!$A$1:$IV$65536,9,FALSE)," ") -> M1A | N29: =IF($A29>0,VLOOKUP($A29,[1]Foglio1!$A$1:$IV$65536,10,FALSE)," ") -> IE3 | O29: =IF($A29>0,VLOOKUP($A29,[1]Foglio1!$A$1:$IV$65536,11,FALSE)," ") -> 230/400 | R29: =IF($A29>0,VLOOKUP($A29,[1]Foglio1!$A$1:$IV$65536,12,FALSE)," ") -> 50 | S29: =IF($A29>0,VLOOKUP($A29,[1]Foglio1!$A$1:$IV$65536,13,FALSE)," ") -> 26,5/15,2 | T29: =IF($A29>0,VLOOKUP($A29,[1]Foglio1!$A$1:$IV$65536,14,FALSE)," ") -> 55 | U29: =IF($A29>0,VLOOKUP($A29,[1]Foglio1!$A$1:$IV$65536,15,FALSE)," ") -> 155(F) | V29: =IF($A29>0,VLOOKUP($A29,[1]Foglio1!$A$1:$IV$65536,16,FALSE)," ") -> 270° | W29: =IF($A29>0,VLOOKUP($A29,[1]Foglio1!$A$1:$IV$65536,17,FALSE)," ") -> TF | X29: =IF($A29>0,IF(VLOOKUP($A29,[1]Foglio1!$A$1:$IV$65536,18,FALSE)<>"-","YES","NO")," ") -> NO | Y29: =IF($A29>0,VLOOKUP($A29,[1]Foglio1!$A$1:$IV$65536,19,FALSE)," ") -> - | Z29: =IF($A29>0,VLOOKUP($A29,[1]Foglio1!$A$1:$IV$65536,20,FALSE)," ") -> - | AA29: =IF($A29>0,VLOOKUP($A29,[1]Foglio1!$A$1:$IV$65536,21,FALSE)," ") -> T | AB29: =IF($A29>0,VLOOKUP($A29,[1]Foglio1!$A$1:$IV$65536,22,FALSE)," ") -> SS+R | AE29: =IF($A29>0,VLOOKUP($A29,[1]Foglio1!$A$1:$IV$65536,23,FALSE)," ") -> - | AF29: =IF($A29>0,VLOOKUP($A29,[1]Foglio1!$A$1:$IV$65536,24,FALSE)," ") -> CLP 220 (-15/+40°C) | AG29: =IF($A29>0,VLOOKUP($A29,[1]Foglio1!$A$1:$IV$65536,25,FALSE)," ") -> KH87/T EDRN132M4 /TF | AH29: =IF($A29>0,VLOOKUP($A29,[1]Foglio1!$A$1:$IV$65536,26,FALSE)," ") -> SEW | AI29: =IF(X29="YES", "YES",IF(A29="","-","NO")) -> NO | AJ29: =IF($A29>0,VLOOKUP($A29,[1]Foglio1!$A$1:$IV$65536,27,FALSE)," ") -> 0 | AK29: =IF($A29>0,VLOOKUP($A29,[1]Foglio1!$A$1:$IV$65536,28,FALSE)," ") -> ATEX22 | AL29: =IF($A29>0,VLOOKUP($A29,[1]Foglio1!$A$1:$IV$65536,31,FALSE)," ") -> 0 | AM29: =IF($A29>0,VLOOKUP($A29,[1]Foglio1!$A$1:$IV$65536,34,FALSE)," ") -> KH87T-EDRN132M4A270-X | AN29: TRM CHN
A30: MR005254 | B30: BE0812C | C30: TM F06 | D30: 1 | E30: =IF($A30>0,VLOOKUP($A30,[1]Foglio1!$A$1:$IV$65536,2,FALSE)," ") -> MR | F30: =IF($A30>0,VLOOKUP($A30,[1]Foglio1!$A$1:$IV$65536,3,FALSE)," ") -> 7.5 | G30: =H30*R30/50 -> 59 | H30: =IF($A30>0,VLOOKUP($A30,[1]Foglio1!$A$1:$IV$65536,4,FALSE)," ") -> 59 | I30: =IF($A30>0,VLOOKUP($A30,[1]Foglio1!$A$1:$IV$65536,5,FALSE)," ") -> KH87 | J30: =IF($A30>0,VLOOKUP($A30,[1]Foglio1!$A$1:$IV$65536,6,FALSE)," ") -> 1210 | K30: =IF($A30>0,VLOOKUP($A30,[1]Foglio1!$A$1:$IV$65536,7,FALSE)," ") -> 24.95 | L30: =IF($A30>0,VLOOKUP($A30,[1]Foglio1!$A$1:$IV$65536,8,FALSE)," ") -> 2.1 | M30: =IF($A30>0,VLOOKUP($A30,[1]Foglio1!$A$1:$IV$65536,9,FALSE)," ") -> M1B | N30: =IF($A30>0,VLOOKUP($A30,[1]Foglio1!$A$1:$IV$65536,10,FALSE)," ") -> IE3 | O30: =IF($A30>0,VLOOKUP($A30,[1]Foglio1!$A$1:$IV$65536,11,FALSE)," ") -> 230/400 | R30: =IF($A30>0,VLOOKUP($A30,[1]Foglio1!$A$1:$IV$65536,12,FALSE)," ") -> 50 | S30: =IF($A30>0,VLOOKUP($A30,[1]Foglio1!$A$1:$IV$65536,13,FALSE)," ") -> 26,5/15,2 | T30: =IF($A30>0,VLOOKUP($A30,[1]Foglio1!$A$1:$IV$65536,14,FALSE)," ") -> 55 | U30: =IF($A30>0,VLOOKUP($A30,[1]Foglio1!$A$1:$IV$65536,15,FALSE)," ") -> 155(F) | V30: =IF($A30>0,VLOOKUP($A30,[1]Foglio1!$A$1:$IV$65536,16,FALSE)," ") -> 270° | W30: =IF($A30>0,VLOOKUP($A30,[1]Foglio1!$A$1:$IV$65536,17,FALSE)," ") -> TF | X30: =IF($A30>0,IF(VLOOKUP($A30,[1]Foglio1!$A$1:$IV$65536,18,FALSE)<>"-","YES","NO")," ") -> NO | Y30: =IF($A30>0,VLOOKUP($A30,[1]Foglio1!$A$1:$IV$65536,19,FALSE)," ") -> - | Z30: =IF($A30>0,VLOOKUP($A30,[1]Foglio1!$A$1:$IV$65536,20,FALSE)," ") -> - | AA30: =IF($A30>0,VLOOKUP($A30,[1]Foglio1!$A$1:$IV$65536,21,FALSE)," ") -> T | AB30: =IF($A30>0,VLOOKUP($A30,[1]Foglio1!$A$1:$IV$65536,22,FALSE)," ") -> SS+R | AE30: =IF($A30>0,VLOOKUP($A30,[1]Foglio1!$A$1:$IV$65536,23,FALSE)," ") -> - | AF30: =IF($A30>0,VLOOKUP($A30,[1]Foglio1!$A$1:$IV$65536,24,FALSE)," ") -> CLP 220 (-15/+40°C) | AG30: =IF($A30>0,VLOOKUP($A30,[1]Foglio1!$A$1:$IV$65536,25,FALSE)," ") -> KH87/T EDRN132M4 /TF | AH30: =IF($A30>0,VLOOKUP($A30,[1]Foglio1!$A$1:$IV$65536,26,FALSE)," ") -> SEW | AI30: =IF(X30="YES", "YES",IF(A30="","-","NO")) -> NO | AJ30: =IF($A30>0,VLOOKUP($A30,[1]Foglio1!$A$1:$IV$65536,27,FALSE)," ") -> 0 | AK30: =IF($A30>0,VLOOKUP($A30,[1]Foglio1!$A$1:$IV$65536,28,FALSE)," ") -> ATEX22 | AL30: =IF($A30>0,VLOOKUP($A30,[1]Foglio1!$A$1:$IV$65536,31,FALSE)," ") -> 0 | AM30: =IF($A30>0,VLOOKUP($A30,[1]Foglio1!$A$1:$IV$65536,34,FALSE)," ") -> KH87T-EDRN132M4B270-X | AN30: TRM CHN
A31: MR005385 | B31: BE0812C | C31: TM F06 | D31: 1 | E31: =IF($A31>0,VLOOKUP($A31,[1]Foglio1!$A$1:$IV$65536,2,FALSE)," ") -> MR | F31: =IF($A31>0,VLOOKUP($A31,[1]Foglio1!$A$1:$IV$65536,3,FALSE)," ") -> 1.1 | G31: =H31*R31/50 -> 7.3 | H31: =IF($A31>0,VLOOKUP($A31,[1]Foglio1!$A$1:$IV$65536,4,FALSE)," ") -> 7.3 | I31: =IF($A31>0,VLOOKUP($A31,[1]Foglio1!$A$1:$IV$65536,5,FALSE)," ") -> FVZ77 | J31: =IF($A31>0,VLOOKUP($A31,[1]Foglio1!$A$1:$IV$65536,6,FALSE)," ") -> 1430 | K31: =IF($A31>0,VLOOKUP($A31,[1]Foglio1!$A$1:$IV$65536,7,FALSE)," ") -> 198.31 | L31: =IF($A31>0,VLOOKUP($A31,[1]Foglio1!$A$1:$IV$65536,8,FALSE)," ") -> 1.05 | M31: =IF($A31>0,VLOOKUP($A31,[1]Foglio1!$A$1:$IV$65536,9,FALSE)," ") -> M5 | N31: =IF($A31>0,VLOOKUP($A31,[1]Foglio1!$A$1:$IV$65536,10,FALSE)," ") -> IE3 | O31: =IF($A31>0,VLOOKUP($A31,[1]Foglio1!$A$1:$IV$65536,11,FALSE)," ") -> 230/400 | R31: =IF($A31>0,VLOOKUP($A31,[1]Foglio1!$A$1:$IV$65536,12,FALSE)," ") -> 50 | S31: =IF($A31>0,VLOOKUP($A31,[1]Foglio1!$A$1:$IV$65536,13,FALSE)," ") -> 4,6/2,65 | T31: =IF($A31>0,VLOOKUP($A31,[1]Foglio1!$A$1:$IV$65536,14,FALSE)," ") -> 55 | U31: =IF($A31>0,VLOOKUP($A31,[1]Foglio1!$A$1:$IV$65536,15,FALSE)," ") -> 155(F) | V31: =IF($A31>0,VLOOKUP($A31,[1]Foglio1!$A$1:$IV$65536,16,FALSE)," ") -> 270° | W31: =IF($A31>0,VLOOKUP($A31,[1]Foglio1!$A$1:$IV$65536,17,FALSE)," ") -> TF | X31: =IF($A31>0,IF(VLOOKUP($A31,[1]Foglio1!$A$1:$IV$65536,18,FALSE)<>"-","YES","NO")," ") -> NO | Y31: =IF($A31>0,VLOOKUP($A31,[1]Foglio1!$A$1:$IV$65536,19,FALSE)," ") -> - | Z31: =IF($A31>0,VLOOKUP($A31,[1]Foglio1!$A$1:$IV$65536,20,FALSE)," ") -> BEHF | AA31: =IF($A31>0,VLOOKUP($A31,[1]Foglio1!$A$1:$IV$65536,21,FALSE)," ") -> - | AB31: =IF($A31>0,VLOOKUP($A31,[1]Foglio1!$A$1:$IV$65536,22,FALSE)," ") -> FC+R | AE31: =IF($A31>0,VLOOKUP($A31,[1]Foglio1!$A$1:$IV$65536,23,FALSE)," ") -> - | AF31: =IF($A31>0,VLOOKUP($A31,[1]Foglio1!$A$1:$IV$65536,24,FALSE)," ") -> CLP 220 (-15/+40°C) | AG31: =IF($A31>0,VLOOKUP($A31,[1]Foglio1!$A$1:$IV$65536,25,FALSE)," ") -> FVZ77EDRN90S4 /BEHF /TF | AH31: =IF($A31>0,VLOOKUP($A31,[1]Foglio1!$A$1:$IV$65536,26,FALSE)," ") -> SEW | AI31: =IF(X31="YES", "YES",IF(A31="","-","NO")) -> NO | AJ31: =IF($A31>0,VLOOKUP($A31,[1]Foglio1!$A$1:$IV$65536,27,FALSE)," ") -> 0 | AK31: =IF($A31>0,VLOOKUP($A31,[1]Foglio1!$A$1:$IV$65536,28,FALSE)," ") -> ATEX22 | AL31: =IF($A31>0,VLOOKUP($A31,[1]Foglio1!$A$1:$IV$65536,31,FALSE)," ") -> BROACHING FOR FV67-DIN 5480N45x2x30x21xH9 Provide rectifier module in the electrical cabinet | AM31: =IF($A31>0,VLOOKUP($A31,[1]Foglio1!$A$1:$IV$65536,34,FALSE)," ") -> FVZ77-EDRN90S4270-X | AN31: TRM CHN
A32: MR005386 | B32: BE0812C | C32: TM F06 | D32: 1 | E32: =IF($A32>0,VLOOKUP($A32,[1]Foglio1!$A$1:$IV$65536,2,FALSE)," ") -> MR | F32: =IF($A32>0,VLOOKUP($A32,[1]Foglio1!$A$1:$IV$65536,3,FALSE)," ") -> 1.1 | G32: =H32*R32/50 -> 7.3 | H32: =IF($A32>0,VLOOKUP($A32,[1]Foglio1!$A$1:$IV$65536,4,FALSE)," ") -> 7.3 | I32: =IF($A32>0,VLOOKUP($A32,[1]Foglio1!$A$1:$IV$65536,5,FALSE)," ") -> FVZ77 | J32: =IF($A32>0,VLOOKUP($A32,[1]Foglio1!$A$1:$IV$65536,6,FALSE)," ") -> 1430 | K32: =IF($A32>0,VLOOKUP($A32,[1]Foglio1!$A$1:$IV$65536,7,FALSE)," ") -> 198.31 | L32: =IF($A32>0,VLOOKUP($A32,[1]Foglio1!$A$1:$IV$65536,8,FALSE)," ") -> 1.05 | M32: =IF($A32>0,VLOOKUP($A32,[1]Foglio1!$A$1:$IV$65536,9,FALSE)," ") -> M6 | N32: =IF($A32>0,VLOOKUP($A32,[1]Foglio1!$A$1:$IV$65536,10,FALSE)," ") -> IE3 | O32: =IF($A32>0,VLOOKUP($A32,[1]Foglio1!$A$1:$IV$65536,11,FALSE)," ") -> 230/400 | R32: =IF($A32>0,VLOOKUP($A32,[1]Foglio1!$A$1:$IV$65536,12,FALSE)," ") -> 50 | S32: =IF($A32>0,VLOOKUP($A32,[1]Foglio1!$A$1:$IV$65536,13,FALSE)," ") -> 4,6/2,65 | T32: =IF($A32>0,VLOOKUP($A32,[1]Foglio1!$A$1:$IV$65536,14,FALSE)," ") -> 55 | U32: =IF($A32>0,VLOOKUP($A32,[1]Foglio1!$A$1:$IV$65536,15,FALSE)," ") -> 155(F) | V32: =IF($A32>0,VLOOKUP($A32,[1]Foglio1!$A$1:$IV$65536,16,FALSE)," ") -> 270° | W32: =IF($A32>0,VLOOKUP($A32,[1]Foglio1!$A$1:$IV$65536,17,FALSE)," ") -> TF | X32: =IF($A32>0,IF(VLOOKUP($A32,[1]Foglio1!$A$1:$IV$65536,18,FALSE)<>"-","YES","NO")," ") -> NO | Y32: =IF($A32>0,VLOOKUP($A32,[1]Foglio1!$A$1:$IV$65536,19,FALSE)," ") -> - | Z32: =IF($A32>0,VLOOKUP($A32,[1]Foglio1!$A$1:$IV$65536,20,FALSE)," ") -> BEHF | AA32: =IF($A32>0,VLOOKUP($A32,[1]Foglio1!$A$1:$IV$65536,21,FALSE)," ") -> - | AB32: =IF($A32>0,VLOOKUP($A32,[1]Foglio1!$A$1:$IV$65536,22,FALSE)," ") -> FC+R | AE32: =IF($A32>0,VLOOKUP($A32,[1]Foglio1!$A$1:$IV$65536,23,FALSE)," ") -> - | AF32: =IF($A32>0,VLOOKUP($A32,[1]Foglio1!$A$1:$IV$65536,24,FALSE)," ") -> CLP 220 (-15/+40°C) | AG32: =IF($A32>0,VLOOKUP($A32,[1]Foglio1!$A$1:$IV$65536,25,FALSE)," ") -> FVZ77EDRN90S4 /BEHF /TF | AH32: =IF($A32>0,VLOOKUP($A32,[1]Foglio1!$A$1:$IV$65536,26,FALSE)," ") -> SEW | AI32: =IF(X32="YES", "YES",IF(A32="","-","NO")) -> NO | AJ32: =IF($A32>0,VLOOKUP($A32,[1]Foglio1!$A$1:$IV$65536,27,FALSE)," ") -> 0 | AK32: =IF($A32>0,VLOOKUP($A32,[1]Foglio1!$A$1:$IV$65536,28,FALSE)," ") -> ATEX22 | AL32: =IF($A32>0,VLOOKUP($A32,[1]Foglio1!$A$1:$IV$65536,31,FALSE)," ") -> BROACHING FOR FV67-DIN 5480N45x2x30x21xH9 Provide rectifier module in the electrical cabinet | AM32: =IF($A32>0,VLOOKUP($A32,[1]Foglio1!$A$1:$IV$65536,34,FALSE)," ") -> FVZ77-EDRN90S4270-X | AN32: TRM CHN
... A44: MR005255 | B44: BE0818C | C44: TM F11 | D44: 1 | E44: =IF($A44>0,VLOOKUP($A44,[1]Foglio1!$A$1:$IV$65536,2,FALSE)," ") -> MR | F44: =IF($A44>0,VLOOKUP($A44,[1]Foglio1!$A$1:$IV$65536,3,FALSE)," ") -> 15 | G44: =H44*R44/50 -> 16 | H44: =IF($A44>0,VLOOKUP($A44,[1]Foglio1!$A$1:$IV$65536,4,FALSE)," ") -> 16 | I44: =IF($A44>0,VLOOKUP($A44,[1]Foglio1!$A$1:$IV$65536,5,FALSE)," ") -> KH127 | J44: =IF($A44>0,VLOOKUP($A44,[1]Foglio1!$A$1:$IV$65536,6,FALSE)," ") -> 8730 | K44: =IF($A44>0,VLOOKUP($A44,[1]Foglio1!$A$1:$IV$65536,7,FALSE)," ") -> 89.89 | L44: =IF($A44>0,VLOOKUP($A44,[1]Foglio1!$A$1:$IV$65536,8,FALSE)," ") -> 1.5 | M44: =IF($A44>0,VLOOKUP($A44,[1]Foglio1!$A$1:$IV$65536,9,FALSE)," ") -> From M1A to M4A - 45° | N44: =IF($A44>0,VLOOKUP($A44,[1]Foglio1!$A$1:$IV$65536,10,FALSE)," ") -> IE3 | O44: =IF($A44>0,VLOOKUP($A44,[1]Foglio1!$A$1:$IV$65536,11,FALSE)," ") -> 230/400 | R44: =IF($A44>0,VLOOKUP($A44,[1]Foglio1!$A$1:$IV$65536,12,FALSE)," ") -> 50 | S44: =IF($A44>0,VLOOKUP($A44,[1]Foglio1!$A$1:$IV$65536,13,FALSE)," ") -> 50/29 | T44: =IF($A44>0,VLOOKUP($A44,[1]Foglio1!$A$1:$IV$65536,14,FALSE)," ") -> 55 | U44: =IF($A44>0,VLOOKUP($A44,[1]Foglio1!$A$1:$IV$65536,15,FALSE)," ") -> 155(F) | V44: =IF($A44>0,VLOOKUP($A44,[1]Foglio1!$A$1:$IV$65536,16,FALSE)," ") -> 270° | W44: =IF($A44>0,VLOOKUP($A44,[1]Foglio1!$A$1:$IV$65536,17,FALSE)," ") -> TF | X44: =IF($A44>0,IF(VLOOKUP($A44,[1]Foglio1!$A$1:$IV$65536,18,FALSE)<>"-","YES","NO")," ") -> YES | Y44: =IF($A44>0,VLOOKUP($A44,[1]Foglio1!$A$1:$IV$65536,19,FALSE)," ") -> - | Z44: =IF($A44>0,VLOOKUP($A44,[1]Foglio1!$A$1:$IV$65536,20,FALSE)," ") -> - | AA44: =IF($A44>0,VLOOKUP($A44,[1]Foglio1!$A$1:$IV$65536,21,FALSE)," ") -> - | AB44: =IF($A44>0,VLOOKUP($A44,[1]Foglio1!$A$1:$IV$65536,22,FALSE)," ") -> FC | AE44: =IF($A44>0,VLOOKUP($A44,[1]Foglio1!$A$1:$IV$65536,23,FALSE)," ") -> - | AF44: =IF($A44>0,VLOOKUP($A44,[1]Foglio1!$A$1:$IV$65536,24,FALSE)," ") -> CLP 220 (-15/+40°C) | AG44: =IF($A44>0,VLOOKUP($A44,[1]Foglio1!$A$1:$IV$65536,25,FALSE)," ") -> KH127DRN160L4 /TF/V | AH44: =IF($A44>0,VLOOKUP($A44,[1]Foglio1!$A$1:$IV$65536,26,FALSE)," ") -> 0 | AI44: =IF(X44="YES", "YES",IF(A44="","-","NO")) -> YES | AJ44: =IF($A44>0,VLOOKUP($A44,[1]Foglio1!$A$1:$IV$65536,27,FALSE)," ") -> 0 | AK44: =IF($A44>0,VLOOKUP($A44,[1]Foglio1!$A$1:$IV$65536,28,FALSE)," ") -> - | AL44: =IF($A44>0,VLOOKUP($A44,[1]Foglio1!$A$1:$IV$65536,31,FALSE)," ") -> 0 | AM44: =IF($A44>0,VLOOKUP($A44,[1]Foglio1!$A$1:$IV$65536,34,FALSE)," ") -> KH127-DRN160L4A270-X# | AN44: TRM CHN
A45: Servofan | D45: 1 | F45: 0,084 | O45: 230/400 | R45: 50 | S45: 0,43/0,25 | T45: 66 | AB45: D | AL45: Also available monophase 230V 0,34A
A46: MR005256 | B46: BE0818C | C46: TM F11 | D46: 1 | E46: =IF($A46>0,VLOOKUP($A46,[1]Foglio1!$A$1:$IV$65536,2,FALSE)," ") -> MR | F46: =IF($A46>0,VLOOKUP($A46,[1]Foglio1!$A$1:$IV$65536,3,FALSE)," ") -> 15 | G46: =H46*R46/50 -> 16 | H46: =IF($A46>0,VLOOKUP($A46,[1]Foglio1!$A$1:$IV$65536,4,FALSE)," ") -> 16 | I46: =IF($A46>0,VLOOKUP($A46,[1]Foglio1!$A$1:$IV$65536,5,FALSE)," ") -> KH127 | J46: =IF($A46>0,VLOOKUP($A46,[1]Foglio1!$A$1:$IV$65536,6,FALSE)," ") -> 8730 | K46: =IF($A46>0,VLOOKUP($A46,[1]Foglio1!$A$1:$IV$65536,7,FALSE)," ") -> 89.89 | L46: =IF($A46>0,VLOOKUP($A46,[1]Foglio1!$A$1:$IV$65536,8,FALSE)," ") -> 1.5 | M46: =IF($A46>0,VLOOKUP($A46,[1]Foglio1!$A$1:$IV$65536,9,FALSE)," ") -> From M1B to M4B - 45° | N46: =IF($A46>0,VLOOKUP($A46,[1]Foglio1!$A$1:$IV$65536,10,FALSE)," ") -> IE3 | O46: =IF($A46>0,VLOOKUP($A46,[1]Foglio1!$A$1:$IV$65536,11,FALSE)," ") -> 230/400 | R46: =IF($A46>0,VLOOKUP($A46,[1]Foglio1!$A$1:$IV$65536,12,FALSE)," ") -> 50 | S46: =IF($A46>0,VLOOKUP($A46,[1]Foglio1!$A$1:$IV$65536,13,FALSE)," ") -> 50/29 | T46: =IF($A46>0,VLOOKUP($A46,[1]Foglio1!$A$1:$IV$65536,14,FALSE)," ") -> 55 | U46: =IF($A46>0,VLOOKUP($A46,[1]Foglio1!$A$1:$IV$65536,15,FALSE)," ") -> 155(F) | V46: =IF($A46>0,VLOOKUP($A46,[1]Foglio1!$A$1:$IV$65536,16,FALSE)," ") -> 270° | W46: =IF($A46>0,VLOOKUP($A46,[1]Foglio1!$A$1:$IV$65536,17,FALSE)," ") -> TF | X46: =IF($A46>0,IF(VLOOKUP($A46,[1]Foglio1!$A$1:$IV$65536,18,FALSE)<>"-","YES","NO")," ") -> YES | Y46: =IF($A46>0,VLOOKUP($A46,[1]Foglio1!$A$1:$IV$65536,19,FALSE)," ") -> - | Z46: =IF($A46>0,VLOOKUP($A46,[1]Foglio1!$A$1:$IV$65536,20,FALSE)," ") -> - | AA46: =IF($A46>0,VLOOKUP($A46,[1]Foglio1!$A$1:$IV$65536,21,FALSE)," ") -> - | AB46: =IF($A46>0,VLOOKUP($A46,[1]Foglio1!$A$1:$IV$65536,22,FALSE)," ") -> FC | AE46: =IF($A46>0,VLOOKUP($A46,[1]Foglio1!$A$1:$IV$65536,23,FALSE)," ") -> - | AF46: =IF($A46>0,VLOOKUP($A46,[1]Foglio1!$A$1:$IV$65536,24,FALSE)," ") -> CLP 220 (-15/+40°C) | AG46: =IF($A46>0,VLOOKUP($A46,[1]Foglio1!$A$1:$IV$65536,25,FALSE)," ") -> KH127DRN160L4 /TF/V | AH46: =IF($A46>0,VLOOKUP($A46,[1]Foglio1!$A$1:$IV$65536,26,FALSE)," ") -> 0 | AI46: =IF(X46="YES", "YES",IF(A46="","-","NO")) -> YES | AJ46: =IF($A46>0,VLOOKUP($A46,[1]Foglio1!$A$1:$IV$65536,27,FALSE)," ") -> 0 | AK46: =IF($A46>0,VLOOKUP($A46,[1]Foglio1!$A$1:$IV$65536,28,FALSE)," ") -> - | AL46: =IF($A46>0,VLOOKUP($A46,[1]Foglio1!$A$1:$IV$65536,31,FALSE)," ") -> 0 | AM46: =IF($A46>0,VLOOKUP($A46,[1]Foglio1!$A$1:$IV$65536,34,FALSE)," ") -> KH127-DRN160L4B270-X# | AN46: TRM CHN
A47: Servofan | D47: 1 | F47: 0,084 | O47: 230/400 | R47: 50 | S47: 0,43/0,25 | T47: 66 | AB47: D | AL47: Also available monophase 230V 0,34A
A49: MR004777 | B49: BE0819C | C49: TM F12 | D49: 1 | E49: =IF($A49>0,VLOOKUP($A49,[1]Foglio1!$A$1:$IV$65536,2,FALSE)," ") -> MR | F49: =IF($A49>0,VLOOKUP($A49,[1]Foglio1!$A$1:$IV$65536,3,FALSE)," ") -> 0.55 | G49: =H49*R49/50 -> 3.9 | H49: =IF($A49>0,VLOOKUP($A49,[1]Foglio1!$A$1:$IV$65536,4,FALSE)," ") -> 3.9 | I49: =IF($A49>0,VLOOKUP($A49,[1]Foglio1!$A$1:$IV$65536,5,FALSE)," ") -> KA77R37 | J49: =IF($A49>0,VLOOKUP($A49,[1]Foglio1!$A$1:$IV$65536,6,FALSE)," ") -> 1210 | K49: =IF($A49>0,VLOOKUP($A49,[1]Foglio1!$A$1:$IV$65536,7,FALSE)," ") -> 367 | L49: =IF($A49>0,VLOOKUP($A49,[1]Foglio1!$A$1:$IV$65536,8,FALSE)," ") -> 1.25 | M49: =IF($A49>0,VLOOKUP($A49,[1]Foglio1!$A$1:$IV$65536,9,FALSE)," ") -> M3B | N49: =IF($A49>0,VLOOKUP($A49,[1]Foglio1!$A$1:$IV$65536,10,FALSE)," ") -> IE3 | O49: =IF($A49>0,VLOOKUP($A49,[1]Foglio1!$A$1:$IV$65536,11,FALSE)," ") -> 230/400 | R49: =IF($A49>0,VLOOKUP($A49,[1]Foglio1!$A$1:$IV$65536,12,FALSE)," ") -> 50 | S49: =IF($A49>0,VLOOKUP($A49,[1]Foglio1!$A$1:$IV$65536,13,FALSE)," ") -> 2,25/1,29 | T49: =IF($A49>0,VLOOKUP($A49,[1]Foglio1!$A$1:$IV$65536,14,FALSE)," ") -> 55 | U49: =IF($A49>0,VLOOKUP($A49,[1]Foglio1!$A$1:$IV$65536,15,FALSE)," ") -> 155(F) | V49: =IF($A49>0,VLOOKUP($A49,[1]Foglio1!$A$1:$IV$65536,16,FALSE)," ") -> 0° | W49: =IF($A49>0,VLOOKUP($A49,[1]Foglio1!$A$1:$IV$65536,17,FALSE)," ") -> TF | X49: =IF($A49>0,IF(VLOOKUP($A49,[1]Foglio1!$A$1:$IV$65536,18,FALSE)<>"-","YES","NO")," ") -> NO | Y49: =IF($A49>0,VLOOKUP($A49,[1]Foglio1!$A$1:$IV$65536,19,FALSE)," ") -> - | Z49: =IF($A49>0,VLOOKUP($A49,[1]Foglio1!$A$1:$IV$65536,20,FALSE)," ") -> BEHF | AA49: =IF($A49>0,VLOOKUP($A49,[1]Foglio1!$A$1:$IV$65536,21,FALSE)," ") -> T | AB49: =IF($A49>0,VLOOKUP($A49,[1]Foglio1!$A$1:$IV$65536,22,FALSE)," ") -> D+R | AE49: =IF($A49>0,VLOOKUP($A49,[1]Foglio1!$A$1:$IV$65536,23,FALSE)," ") -> - | AF49: =IF($A49>0,VLOOKUP($A49,[1]Foglio1!$A$1:$IV$65536,24,FALSE)," ") -> CLP 220 (-15/+40°C) | AG49: =IF($A49>0,VLOOKUP($A49,[1]Foglio1!$A$1:$IV$65536,25,FALSE)," ") -> KA77R37/T DRN80MK4 /BEHF /TF | AH49: =IF($A49>0,VLOOKUP($A49,[1]Foglio1!$A$1:$IV$65536,26,FALSE)," ") -> SEW | AI49: =IF(X49="YES", "YES",IF(A49="","-","NO")) -> NO | AJ49: =IF($A49>0,VLOOKUP($A49,[1]Foglio1!$A$1:$IV$65536,27,FALSE)," ") -> 0 | AK49: =IF($A49>0,VLOOKUP($A49,[1]Foglio1!$A$1:$IV$65536,28,FALSE)," ") -> - | AL49: =IF($A49>0,VLOOKUP($A49,[1]Foglio1!$A$1:$IV$65536,31,FALSE)," ") -> 0 | AM49: =IF($A49>0,VLOOKUP($A49,[1]Foglio1!$A$1:$IV$65536,34,FALSE)," ") -> KA77R37T-DRN80MK4B0-X | AN49: TRM CHN
A51: MR005257 | B51: BE0820C | C51: TM F13 | D51: 1 | E51: =IF($A51>0,VLOOKUP($A51,[1]Foglio1!$A$1:$IV$65536,2,FALSE)," ") -> MR | F51: =IF($A51>0,VLOOKUP($A51,[1]Foglio1!$A$1:$IV$65536,3,FALSE)," ") -> 15 | G51: =H51*R51/50 -> 48 | H51: =IF($A51>0,VLOOKUP($A51,[1]Foglio1!$A$1:$IV$65536,4,FALSE)," ") -> 48 | I51: =IF($A51>0,VLOOKUP($A51,[1]Foglio1!$A$1:$IV$65536,5,FALSE)," ") -> KH97 | J51: =IF($A51>0,VLOOKUP($A51,[1]Foglio1!$A$1:$IV$65536,6,FALSE)," ") -> 2990 | K51: =IF($A51>0,VLOOKUP($A51,[1]Foglio1!$A$1:$IV$65536,7,FALSE)," ") -> 30.82 | L51: =IF($A51>0,VLOOKUP($A51,[1]Foglio1!$A$1:$IV$65536,8,FALSE)," ") -> 1.45 | M51: =IF($A51>0,VLOOKUP($A51,[1]Foglio1!$A$1:$IV$65536,9,FALSE)," ") -> From M1A to M4A - 70° | N51: =IF($A51>0,VLOOKUP($A51,[1]Foglio1!$A$1:$IV$65536,10,FALSE)," ") -> IE3 | O51: =IF($A51>0,VLOOKUP($A51,[1]Foglio1!$A$1:$IV$65536,11,FALSE)," ") -> 230/400 | R51: =IF($A51>0,VLOOKUP($A51,[1]Foglio1!$A$1:$IV$65536,12,FALSE)," ") -> 50 | S51: =IF($A51>0,VLOOKUP($A51,[1]Foglio1!$A$1:$IV$65536,13,FALSE)," ") -> 50/29 | T51: =IF($A51>0,VLOOKUP($A51,[1]Foglio1!$A$1:$IV$65536,14,FALSE)," ") -> 55 | U51: =IF($A51>0,VLOOKUP($A51,[1]Foglio1!$A$1:$IV$65536,15,FALSE)," ") -> 155(F) | V51: =IF($A51>0,VLOOKUP($A51,[1]Foglio1!$A$1:$IV$65536,16,FALSE)," ") -> 270° | W51: =IF($A51>0,VLOOKUP($A51,[1]Foglio1!$A$1:$IV$65536,17,FALSE)," ") -> TF | X51: =IF($A51>0,IF(VLOOKUP($A51,[1]Foglio1!$A$1:$IV$65536,18,FALSE)<>"-","YES","NO")," ") -> NO | Y51: =IF($A51>0,VLOOKUP($A51,[1]Foglio1!$A$1:$IV$65536,19,FALSE)," ") -> Free rotation CCW | Z51: =IF($A51>0,VLOOKUP($A51,[1]Foglio1!$A$1:$IV$65536,20,FALSE)," ") -> - | AA51: =IF($A51>0,VLOOKUP($A51,[1]Foglio1!$A$1:$IV$65536,21,FALSE)," ") -> T | AB51: =IF($A51>0,VLOOKUP($A51,[1]Foglio1!$A$1:$IV$65536,22,FALSE)," ") -> SS | AE51: =IF($A51>0,VLOOKUP($A51,[1]Foglio1!$A$1:$IV$65536,23,FALSE)," ") -> - | AF51: =IF($A51>0,VLOOKUP($A51,[1]Foglio1!$A$1:$IV$65536,24,FALSE)," ") -> CLP 220 (-15/+40°C) | AG51: =IF($A51>0,VLOOKUP($A51,[1]Foglio1!$A$1:$IV$65536,25,FALSE)," ") -> KH97/T DRN160L4 /RS /TF | AH51: =IF($A51>0,VLOOKUP($A51,[1]Foglio1!$A$1:$IV$65536,26,FALSE)," ") -> SEW | AI51: =IF(X51="YES", "YES",IF(A51="","-","NO")) -> NO | AJ51: =IF($A51>0,VLOOKUP($A51,[1]Foglio1!$A$1:$IV$65536,27,FALSE)," ") -> 0 | AK51: =IF($A51>0,VLOOKUP($A51,[1]Foglio1!$A$1:$IV$65536,28,FALSE)," ") -> - | AL51: =IF($A51>0,VLOOKUP($A51,[1]Foglio1!$A$1:$IV$65536,31,FALSE)," ") -> 0 | AM51: =IF($A51>0,VLOOKUP($A51,[1]Foglio1!$A$1:$IV$65536,34,FALSE)," ") -> KH97T-DRN160L4A270-X | AN51: TRM CHN
