Workbook
Name _pm110: Foglio2!$D$9
Name _pm1100: Foglio2!$D$17
Name _pm12: Foglio2!$D$3
Name _pm150: Foglio2!$D$10
Name _pm1500: Foglio2!$D$18
Name _pm18: Foglio2!$D$4
Name _pm1850: Foglio2!$D$19
Name _pm220: Foglio2!$D$11
Name _pm2200: Foglio2!$D$20
Name _pm25: Foglio2!$D$5
Name _pm300: Foglio2!$D$12
Name _pm3000: Foglio2!$D$21
Name _pm37: Foglio2!$D$6
Name _pm3700: Foglio2!$D$22
Name _pm400: Foglio2!$D$13
Name _pm4500: Foglio2!$D$23
Name _pm55: Foglio2!$D$7
Name _pm550: Foglio2!$D$14
Name _pm75: Foglio2!$D$8
Name _pm750: Foglio2!$D$15
Name _pm920: Foglio2!$D$16

Sheet Foglio1
A1: Project ° | B1: INTERNAL ORDER CONF NR | C1: Link to PE folder | D1: CUSTOMER | E1: FINAL CUSTOMER | F1: PLANT | G1: DESCRIPTION | H1: Location | I1: Vendor | J1: YEAR | K1: Project Engineer | L1: DELIVERY | M1: REMARKS | N1: MOTOR & SENSOR LIST DELIVERED TO PURCHASE DEPT. AND TO CUSTOMER | O1: PROJECT STATUS | P1: FOLDER NAME | Q1: Column17 | R1: Column18 | S1: Column19
A2: 700 | B2: AT063 | C2: link | D2: DIEFFENBACHER | E2: ARAUCO | F2: GRAYLING MDP | H2: USA | J2: 2016 | K2: Brugnoli | L2: 42845 | N2: YES | O2: Completato | P2: 700-DIEFFENBACHER-ARAUCO-GRAYLING MDP-2016
A3: 700 | B3: AS826 | C3: link | D3: DIEFFENBACHER | E3: ARAUCO | F3: GRAYLING MDP | H3: USA | J3: 2016 | K3: Brugnoli | L3: 42870 | N3: YES | O3: Completato | P3: 700-DIEFFENBACHER-ARAUCO-GRAYLING MDP-2016
A4: 700 | B4: AS822 | C4: link | D4: DIEFFENBACHER | E4: ARAUCO | F4: GRAYLING MDP | H4: USA | J4: 2016 | K4: Brugnoli | L4: 42916 | N4: YES | O4: Completato | P4: 700-DIEFFENBACHER-ARAUCO-GRAYLING MDP-2016
A5: 700 | B5: AS857 | C5: link | D5: DIEFFENBACHER | E5: ARAUCO | F5: GRAYLING MDP | H5: USA | J5: 2016 | K5: Brugnoli | L5: 42958 | N5: NOT REQUIRED | O5: Completato | P5: 700-DIEFFENBACHER-ARAUCO-GRAYLING MDP-2016
A6: 700 | B6: AT292 | C6: link | D6: DIEFFENBACHER | E6: ARAUCO | F6: GRAYLING MDP | H6: USA | J6: 2016 | K6: Brugnoli | L6: 42968 | N6: YES | O6: Completato | P6: 700-DIEFFENBACHER-ARAUCO-GRAYLING MDP-2016
A7: 701 | B7: AS202 | C7: link | D7: BIPAN S.P.A | F7: NEW SILO FIBRA | H7: ITALY | J7: 2016 | N7: - | O7: Completato | P7: 701-BIPAN S.P.A--NEW SILO FIBRA-2016
A8: 702 | B8: AS132 | C8: link | D8: IMAL | F8: RURSUS | H8: BELGIUM | J8: 2016 | N8: - | O8: Completato | P8: 702-IMAL--RURSUS-2016
A9: 703 | B9: AS185 | C9: link | D9: IMAL | F9: PG BISON | H9: SUD AFRICA | J9: 2016 | N9: - | O9: Completato | P9: 703-IMAL--PG BISON-2016
A10: 704 | B10: AS184 | C10: link | D10: PG BISON | E10: PG BISON | F10: NEW PB PLANT | H10: SUD AFRICA | J10: 2016 | N10: - | O10: Completato | P10: 704-PG BISON-PG BISON-NEW PB PLANT-2016
A11: 705 | B11: AS197 | C11: link | D11: DELHEZ BOIS | F11: IN-OUT NEW DRIER | H11: BELGIUM | J11: 2016 | N11: - | O11: Completato | P11: 705-DELHEZ BOIS--IN-OUT NEW DRIER-2016
A12: 706 | B12: AS196 | C12: link | D12: TECHNIC ONE | E12: DELHEZ BOIS | F12: NEW DRIER INFEED | H12: BELGIUM | J12: 2016 | N12: - | O12: Completato | P12: 706-TECHNIC ONE-DELHEZ BOIS-NEW DRIER INFEED-2016
A13: 707 | B13: AS253 | C13: link | D13: SONAE | F13: OLIVEIRA DO HOSPITAL | G13: OUTFEED FALCON MILLS | H13: PORTUGAL | J13: 2016 | N13: - | O13: Completato | P13: 707-SONAE--OLIVEIRA DO HOSPITAL-OUTFEED FALCON MILLS-2016
A14: 708 | B14: AS370-AS371 | C14: link | D14: SIA CONTIPLUS | E14: KRONOSPAN | F14: BURGOS-VARIOUS | H14: SPAIN | J14: 2016 | N14: - | O14: Completato | P14: 708-SIA CONTIPLUS-KRONOSPAN-BURGOS-VARIOUS-2016
A15: 709 | B15: AS195 | C15: link | D15: INSTALMEC | E15: KRONOSPAN | F15: BURGOS-NEW DRIER | H15: SPAIN | J15: 2016 | M15: PER IMPIANTO VEDI FALDONE NR.698 | N15: - | O15: Completato | P15: 709-INSTALMEC-KRONOSPAN-BURGOS-NEW DRIER-2016
A16: 710 | B16: AS310 | C16: link | D16: DIEFFENBACHER | E16: GREENPLY | F16: NEW MDF PLANT 2 | H16: INDIA | J16: 2016 | N16: YES | O16: Completato | P16: 710-DIEFFENBACHER-GREENPLY -NEW MDF PLANT 2-2016
A17: 711 | B17: AS302 | C17: link | D17: KRONOSPAN | F17: SZCZECINEK-NEW TB800 | H17: POLAND | J17: 2016 | N17: - | O17: Completato | P17: 711-KRONOSPAN--SZCZECINEK-NEW TB800-2016
A18: 712 | B18: AS339 | C18: link | D18: IMAL | F18: GROUP FRANCOIS BELGIUM | G18: VARIOUS | H18: BELGIUM | J18: 2016 | N18: - | O18: Completato | P18: 712-IMAL--GROUP FRANCOIS BELGIUM-VARIOUS-2016
A19: 713 | B19: AS213 | C19: link | D19: GRUPPO MAURO SAVIOLA | F19: SIA VIADANA | G19: VARIOUS | H19: ITALY | J19: 2016 | N19: - | O19: Completato | P19: 713-GRUPPO MAURO SAVIOLA--SIA VIADANA-VARIOUS-2016
A20: 714 | B20: AS348 | C20: link | D20: DIEFFENBACHER | E20: KRONOSPAN | F20: SWISS KRONO | H20: SWITZERLAND | J20: 2016 | M20: AT062, AT202 | N20: - | O20: Completato | P20: 714-DIEFFENBACHER-KRONOSPAN-SWISS KRONO-2016
A21: 715 | B21: AS373 | C21: link | D21: TRASMEC CHINA | E21: BORG | F21: NEW BELT CONVEYORS | H21: AUSTRALIA | J21: 2016 | K21: Longari | N21: - | O21: Completato | P21: 715-TRASMEC CHINA-BORG-NEW BELT CONVEYORS-2016
A22: 716 | C22: link | D22: TRASMEC CHINA | E22: DIEFFENBACHER | F22: PANEL PLUS MDF II | H22: THAILAND | J22: 2016 | M22: DIRETTO TRASMEC CHINA | N22: - | O22: Completato | P22: 716-TRASMEC CHINA-DIEFFENBACHER-PANEL PLUS MDF II-2016
A23: 717 | B23: AS567 | C23: link | D23: PAL | E23: BORG | F23: NEW PB PLANT | G23: VARIOUS SCREWS - AUSTRALIA 1 | H23: AUSTRALIA | J23: 2016 | L23: 42689 | N23: - | O23: Completato | P23: 717-PAL-BORG-NEW PB PLANT-VARIOUS SCREWS - AUSTRALIA 1-2016
A24: 718 | B24: AS358 parte A | C24: link | D24: BORG | F24: NEW PB PLANT | H24: AUSTRALIA | J24: 2016 | K24: Longari | L24: 42853 | N24: YES | O24: Completato | P24: 718-BORG--NEW PB PLANT-2016
A25: 718 | B25: AS358 parte B | C25: link | D25: BORG | F25: NEW PB PLANT | H25: AUSTRALIA | J25: 2016 | K25: Longari | L25: 43018 | N25: YES | O25: Completato | P25: 718-BORG--NEW PB PLANT-2016
A26: 718 | B26: AT675 | C26: link | D26: BORG | F26: NEW PB PLANT | H26: AUSTRALIA | J26: 2016 | K26: Longari | L26: 43089 | N26: NOT REQUIRED | O26: Completato | P26: 718-BORG--NEW PB PLANT-2016
A27: 719 | B27: AS665 | C27: link | D27: PANEL PLUS | E27: PANEL PLUS | F27: NEW MDF 2 PLANT PROJECT | H27: THAILAND | J27: 2016 | K27: Brugnoli | M27: Altro ordine AT006 | N27: YES | O27: Completato | P27: 719-PANEL PLUS-PANEL PLUS-NEW MDF 2 PLANT PROJECT-2016
A28: 720 | B28: AS650 | C28: link | D28: DIEFFENBACHER | E28: NORBORD | F28: INVERNESS OSB | H28: SCOTLAND | J28: 2016 | K28: Brugnoli | N28: YES | O28: Completato | P28: 720-DIEFFENBACHER-NORBORD-INVERNESS OSB-2016
A29: 721 | B29: AS650 | C29: link | D29: DIEFFENBACHER | E29: NORBORD | F29: INVERNESS OSB | G29: SWIVEL SCREWS | H29: SCOTLAND | J29: 2016 | K29: Brugnoli | N29: YES | O29: Completato | P29: 721-DIEFFENBACHER-NORBORD-INVERNESS OSB-SWIVEL SCREWS-2016
A30: 722 | C30: link | D30: INSTALMEC | E30: KRONOSPAN | F30: CHIRK | H30: ENGLAND | J30: 2016 | O30: Morto | P30: 722-INSTALMEC-KRONOSPAN-CHIRK--2016
A31: 723 | C31: link | D31: KRONOSPAN | E31: KRONOSPAN | F31: FALCO-NEW DRIER | H31: HUNGARY | J31: 2016 | O31: Morto | P31: 723-KRONOSPAN-KRONOSPAN-FALCO-NEW DRIER--2016
A32: 724 | B32: AS771 | C32: link | D32: IMAL | E32: NORBORD | F32: INVERNESS OSB | H32: SCOTLAND | J32: 2016 | K32: Franzini | L32: 14/04/2017;31/03/2017 | M32: Altro ordine: AT040; AT116 | N32: YES | O32: Completato | P32: 724-IMAL-NORBORD-INVERNESS OSB--2016
A33: 725 | B33: AT583 | C33: link | D33: IMAL | E33: KRONOSPAN | F33: SANEM OSB | H33: LUXENBOURG | J33: 2016 | K33: Franzini/Brugnoli | L33: 43136 | N33: YES | O33: Completato | P33: 725-IMAL-KRONOSPAN-SANEM OSB--2016
A34: 726 | C34: link | D34: IMAL | E34: PG BISON | F34: PB PLANT - STEP 2 | H34: SUD AFRICA | J34: 2016 | O34: Morto | P34: 726-IMAL-PG BISON-PB PLANT - STEP 2--2016
A35: 727 | B35: AS747 | C35: link | D35: BIPAN S.P.A | F35: BIPAN S.P.A | H35: ITALY | J35: 2016 | L35: 42724 | N35: YES | O35: Completato | P35: 727-BIPAN S.P.A--BIPAN S.P.A--2016
A36: 728 | B36: AS725 | C36: link | D36: KRONOSPAN | F36: SALAS | H36: SPAIN | J36: 2016 | K36: Fragale | L36: 42720 | N36: YES | O36: Completato | P36: 728-KRONOSPAN--SALAS--2016
A37: 729 | B37: AS767 | C37: link | D37: DIEFFENBACHER | F37: PLACAS BRASIL | H37: BRASIL | J37: 2016 | L37: 42870 | N37: YES | O37: Completato | P37: 729-DIEFFENBACHER--PLACAS BRASIL--2016
A38: 730 | B38: AS763 | C38: link | D38: PANEL PLUS | E38: PANEL PLUS | F38: MDF 1 -CONVEYORS | H38: THAILAND | J38: 2016 | K38: Brugnoli | N38: YES | O38: Completato | P38: 730-PANEL PLUS-PANEL PLUS-MDF 1 -CONVEYORS-2016
A39: 731 | B39: AS569 | C39: link | D39: PAL | E39: BORG | F39: NEW PB PLANT | G39: AUSTRALIA 2 | H39: AUSTRALIA | J39: 2016 | K39: Longari | L39: 43084 | N39: YES | O39: Completato | P39: 731-PAL-BORG-NEW PB PLANT-2016
A40: 732 | B40: AS788 | C40: link | D40: FANTONI | F40: ALIMENTAZ NUOVA CALDAIA | H40: ITALY | J40: 2016 | K40: Longari | L40: 42840 | N40: YES | O40: Completato | P40: 732-FANTONI--ALIMENTAZ NUOVA CALDAIA-2016
...

Sheet SL
A1: SENSOR LIST | O1: TRASMEC s.r.l. Via Bergamo, 2/a - 26011 Casalbuttano (CR) Technical dept.
A2: Customer | B2: =IFERROR(IF(VLOOKUP(TRIM($B$6), Foglio1!$B$2:$I$1167, 3, FALSE) = 0, "", VLOOKUP(TRIM($B$6), Foglio1!$B$2:$I$1167, 3, FALSE)), "-") -> SOBONO ENERGY | F2: Rev.N° | G2: 0 | H2: by | I2: F.F. | K2: date | L2: 45755 | M2: Status
A3: Final Customer | B3: =IFERROR(IF(VLOOKUP(TRIM($B$6), Foglio1!$B$2:$I$1167, 4, FALSE) = 0, "", VLOOKUP(TRIM($B$6), Foglio1!$B$2:$I$1167, 4, FALSE)), "-") | F3: Rev.N° | G3: 1 | H3: by | I3: F.F. | K3: date | L3: 45824
A4: Project | B4: =IFERROR(IF(VLOOKUP(TRIM($B$6), Foglio1!$B$2:$I$1167, 5, FALSE) = 0, "", VLOOKUP(TRIM($B$6), Foglio1!$B$2:$I$1167, 5, FALSE)), "-") -> Energy Plant | F4: Rev.N° | G4: 2 | H4: by | I4: F.F. | K4: date | L4: 45855 | M4: RELEASED
A5: Location | B5: =IFERROR(IF(VLOOKUP(TRIM($B$6), Foglio1!$B$2:$I$1167, 7, FALSE) = 0, "", VLOOKUP(TRIM($B$6), Foglio1!$B$2:$I$1167, 7, FALSE)), "-") -> SINGAPORE | F5: Rev.N° | H5: by | K5: date
A6: Order n° | B6: IT00125COC00050 | D6: Project N° | E6: =IFERROR(INDEX(Foglio1!A2:A1167, MATCH(TRIM($B$6), Foglio1!B2:B1167, 0)),"-") -> IT0012025TRT00044 | F6: Rev.N° | H6: by | K6: date
A7: REFER TO THE INTERLOCKING FILES FOR THE DESCRIPTION OF THE FUNCTION OF EACH SENSOR.
A9: ITEM NUMBER | B9: TRASMEC JOB N° | C9: LAYOUT POSITION | D9: QTY | E9: DESIGNATION | I9: MODEL | J9: OPERATING VOLTAGE | M9: SUPPLIER | N9: ATEX | O9: NOTE
L10: FREQUENCY
J11: VOLT | K11: AC/DC | L11: Hz
A13: SE0010 | B13: BE0805C | C13: TM F00 | D13: 2 | E13: LIMIT SWITCH | I13: =IF(A13>0,VLOOKUP(A13,[1]SE!$A$1:$K$65536,5,FALSE)," ") -> XS630B1PAL2 | J13: =IF(A13>0,VLOOKUP(A13,[1]SE!$A$1:$K$65536,6,FALSE)," ") -> 24 | K13: =IF(A13>0,VLOOKUP(A13,[1]SE!$A$1:$K$65536,7,FALSE)," ") -> DC | L13: =IF(A13>0,VLOOKUP(A13,[1]SE!$A$1:$K$65536,8,FALSE)," ") -> 0 | M13: =IF(A13>0,VLOOKUP(A13,[1]SE!$A$1:$K$65536,4,FALSE)," ") -> Telemecanique | N13: =IF(A13>0,VLOOKUP(A13,[1]SE!$A$1:$K$65536,10,FALSE)," ") -> 0 | O13: =IF(A13>0,VLOOKUP(A13,[1]SE!$A$1:$K$65536,11,FALSE)," ") -> 0 | P13: TRM CHN
A15: SE0010 | B15: BE0806C | C15: TM F01 | D15: 1 | E15: SWITCH OVERFLOW | I15: =IF(A15>0,VLOOKUP(A15,[1]SE!$A$1:$K$65536,5,FALSE)," ") -> XS630B1PAL2 | J15: =IF(A15>0,VLOOKUP(A15,[1]SE!$A$1:$K$65536,6,FALSE)," ") -> 24 | K15: =IF(A15>0,VLOOKUP(A15,[1]SE!$A$1:$K$65536,7,FALSE)," ") -> DC | L15: =IF(A15>0,VLOOKUP(A15,[1]SE!$A$1:$K$65536,8,FALSE)," ") -> 0 | M15: =IF(A15>0,VLOOKUP(A15,[1]SE!$A$1:$K$65536,4,FALSE)," ") -> Telemecanique | N15: =IF(A15>0,VLOOKUP(A15,[1]SE!$A$1:$K$65536,10,FALSE)," ") -> 0 | O15: =IF(A15>0,VLOOKUP(A15,[1]SE!$A$1:$K$65536,11,FALSE)," ") -> 0 | P15: TRM ITY
A16: SE1022 | B16: BE0806C | C16: TM F01 | D16: 1 | E16: SPEED CONTROL - RELATIVE ENCODER | I16: =IF(A16>0,VLOOKUP(A16,[1]SE!$A$1:$K$65536,5,FALSE)," ") -> ROTACOD AS58-12-04-AI12-10-PT-RM8 | J16: =IF(A16>0,VLOOKUP(A16,[1]SE!$A$1:$K$65536,6,FALSE)," ") -> 24 | K16: =IF(A16>0,VLOOKUP(A16,[1]SE!$A$1:$K$65536,7,FALSE)," ") -> DC | L16: =IF(A16>0,VLOOKUP(A16,[1]SE!$A$1:$K$65536,8,FALSE)," ") -> 0 | M16: =IF(A16>0,VLOOKUP(A16,[1]SE!$A$1:$K$65536,4,FALSE)," ") -> LIKA | N16: =IF(A16>0,VLOOKUP(A16,[1]SE!$A$1:$K$65536,10,FALSE)," ") -> NO | O16: =IF(A16>0,VLOOKUP(A16,[1]SE!$A$1:$K$65536,11,FALSE)," ") -> WITH SE1023 E SE1020. Output 4-20mA, 4096 info/round, 16 rounds , shaft Ø10mm, radial connector M12 8pin | P16: TRM ITY
A17: SE1023 | D17: 1 | I17: =IF(A17>0,VLOOKUP(A17,[1]SE!$A$1:$K$65536,5,FALSE)," ") -> EC-M12F8-LK-M8-L050 | J17: =IF(A17>0,VLOOKUP(A17,[1]SE!$A$1:$K$65536,6,FALSE)," ") -> 0 | K17: =IF(A17>0,VLOOKUP(A17,[1]SE!$A$1:$K$65536,7,FALSE)," ") -> 0 | L17: =IF(A17>0,VLOOKUP(A17,[1]SE!$A$1:$K$65536,8,FALSE)," ") -> 0 | M17: =IF(A17>0,VLOOKUP(A17,[1]SE!$A$1:$K$65536,4,FALSE)," ") -> LIKA | N17: =IF(A17>0,VLOOKUP(A17,[1]SE!$A$1:$K$65536,10,FALSE)," ") -> NO | O17: =IF(A17>0,VLOOKUP(A17,[1]SE!$A$1:$K$65536,11,FALSE)," ") -> Cable connector M12 8pin, on the other side free cables | P17: TRM ITY
A18: SE1020 | D18: 1 | I18: =IF(A18>0,VLOOKUP(A18,[1]SE!$A$1:$K$65536,5,FALSE)," ") -> PAN -10 | J18: =IF(A18>0,VLOOKUP(A18,[1]SE!$A$1:$K$65536,6,FALSE)," ") -> 0 | K18: =IF(A18>0,VLOOKUP(A18,[1]SE!$A$1:$K$65536,7,FALSE)," ") -> 0 | L18: =IF(A18>0,VLOOKUP(A18,[1]SE!$A$1:$K$65536,8,FALSE)," ") -> 0 | M18: =IF(A18>0,VLOOKUP(A18,[1]SE!$A$1:$K$65536,4,FALSE)," ") -> LIKA | N18: =IF(A18>0,VLOOKUP(A18,[1]SE!$A$1:$K$65536,10,FALSE)," ") -> NO | O18: =IF(A18>0,VLOOKUP(A18,[1]SE!$A$1:$K$65536,11,FALSE)," ") -> Coupling joint Ø10 - Ø10 | P18: TRM ITY
A19: PN1005-9 | B19: BE0806C | C19: TM F01 | D19: 1 | E19: WEIGHING SYSTEM | I19: 350i/a | J19: 24 | K19: DC | L19: 0 | M19: UTILCELL | N19: NO | O19: This component does not need power. It is powered by the transmitter PN1009 | P19: TRM ITY
A20: PN1006 | D20: 1 | I20: Silent-block with lift-off prevention mod. 35909 | J20: 0 | K20: 0 | L20: 0 | M20: UTILCELL | N20: NO | P20: TRM ITY
A21: PN1007 | D21: 1 | I21: Base plate mod. 35911 | J21: 0 | K21: 0 | L21: 0 | M21: UTILCELL | N21: NO | P21: TRM ITY
A22: PN1008 | D22: 1 | I22: Junction box 4 load cells mod. 89053 | J22: 0 | K22: 0 | L22: 0 | M22: UTILCELL | N22: NO | P22: TRM ITY
A23: PN1009 | D23: 1 | I23: Weighing transmitter SWIFT RAIL RS+ANALOG mod.89450 | J23: 24 | K23: DC | L23: 0 | M23: UTILCELL | N23: NO | O23: Output 0-20mA | P23: TRM ITY
A24: PN1010 | D24: 1 | I24: Mounting box for transmitter mod.89458 | J24: 0 | K24: 0 | L24: 0 | M24: UTILCELL | N24: NO | P24: TRM ITY
A25: PN1011 | D25: 1 | I25: Load cell cable 20m rif.89009 | J25: 0 | K25: 0 | L25: 0 | M25: UTILCELL | N25: NO | P25: TRM ITY
A27: SE0110 | B27: BE0807C | C27: TM F02 | D27: 1 | E27: SWITCH OVERFLOW | I27: =IF(A27>0,VLOOKUP(A27,[1]SE!$A$1:$K$65536,5,FALSE)," ") -> XS630B1PAL2EX | J27: =IF(A27>0,VLOOKUP(A27,[1]SE!$A$1:$K$65536,6,FALSE)," ") -> 10 ÷ 48 | K27: =IF(A27>0,VLOOKUP(A27,[1]SE!$A$1:$K$65536,7,FALSE)," ") -> DC | L27: =IF(A27>0,VLOOKUP(A27,[1]SE!$A$1:$K$65536,8,FALSE)," ") -> 0 | M27: =IF(A27>0,VLOOKUP(A27,[1]SE!$A$1:$K$65536,4,FALSE)," ") -> Telemecanique | N27: =IF(A27>0,VLOOKUP(A27,[1]SE!$A$1:$K$65536,10,FALSE)," ") -> ATEX21 | O27: =IF(A27>0,VLOOKUP(A27,[1]SE!$A$1:$K$65536,11,FALSE)," ") -> cable 2 m | P27: TRM CHN
A28: SE0110 | B28: BE0807C | C28: TM F02 | D28: 4 | E28: SWITCH CHAIN CONTROL | I28: =IF(A28>0,VLOOKUP(A28,[1]SE!$A$1:$K$65536,5,FALSE)," ") -> XS630B1PAL2EX | J28: =IF(A28>0,VLOOKUP(A28,[1]SE!$A$1:$K$65536,6,FALSE)," ") -> 10 ÷ 48 | K28: =IF(A28>0,VLOOKUP(A28,[1]SE!$A$1:$K$65536,7,FALSE)," ") -> DC | L28: =IF(A28>0,VLOOKUP(A28,[1]SE!$A$1:$K$65536,8,FALSE)," ") -> 0 | M28: =IF(A28>0,VLOOKUP(A28,[1]SE!$A$1:$K$65536,4,FALSE)," ") -> Telemecanique | N28: =IF(A28>0,VLOOKUP(A28,[1]SE!$A$1:$K$65536,10,FALSE)," ") -> ATEX21 | O28: =IF(A28>0,VLOOKUP(A28,[1]SE!$A$1:$K$65536,11,FALSE)," ") -> cable 2 m | P28: TRM CHN
A29: SE0004 | B29: BE0807C | C29: TM F02 | D29: 2 | E29: SWITCH TORQUE CONTROL | I29: =IF(A29>0,VLOOKUP(A29,[1]SE!$A$1:$K$65536,5,FALSE)," ") -> IF504A | J29: =IF(A29>0,VLOOKUP(A29,[1]SE!$A$1:$K$65536,6,FALSE)," ") -> 24 | K29: =IF(A29>0,VLOOKUP(A29,[1]SE!$A$1:$K$65536,7,FALSE)," ") -> DC | L29: =IF(A29>0,VLOOKUP(A29,[1]SE!$A$1:$K$65536,8,FALSE)," ") -> 0 | M29: =IF(A29>0,VLOOKUP(A29,[1]SE!$A$1:$K$65536,4,FALSE)," ") -> IFM | N29: =IF(A29>0,VLOOKUP(A29,[1]SE!$A$1:$K$65536,10,FALSE)," ") -> ATEX22 | O29: =IF(A29>0,VLOOKUP(A29,[1]SE!$A$1:$K$65536,11,FALSE)," ") -> 0 | P29: TRM ITY
A30: SE0003 | B30: BE0807C | C30: TM F02 | D30: 2 | E30: CABLE | I30: =IF(A30>0,VLOOKUP(A30,[1]SE!$A$1:$K$65536,5,FALSE)," ") -> EVC27A | J30: =IF(A30>0,VLOOKUP(A30,[1]SE!$A$1:$K$65536,6,FALSE)," ") -> 0 | K30: =IF(A30>0,VLOOKUP(A30,[1]SE!$A$1:$K$65536,7,FALSE)," ") -> 0 | L30: =IF(A30>0,VLOOKUP(A30,[1]SE!$A$1:$K$65536,8,FALSE)," ") -> 0 | M30: =IF(A30>0,VLOOKUP(A30,[1]SE!$A$1:$K$65536,4,FALSE)," ") -> IFM | N30: =IF(A30>0,VLOOKUP(A30,[1]SE!$A$1:$K$65536,10,FALSE)," ") -> ATEX22 | O30: =IF(A30>0,VLOOKUP(A30,[1]SE!$A$1:$K$65536,11,FALSE)," ") -> CONNECTOR AND CABLE ATEX22 | P30: TRM ITY
A31: SE0110 | B31: BE0807C | C31: TM F02 | D31: 1 | E31: SPEED CONTROL | I31: =IF(A31>0,VLOOKUP(A31,[1]SE!$A$1:$K$65536,5,FALSE)," ") -> XS630B1PAL2EX | J31: =IF(A31>0,VLOOKUP(A31,[1]SE!$A$1:$K$65536,6,FALSE)," ") -> 10 ÷ 48 | K31: =IF(A31>0,VLOOKUP(A31,[1]SE!$A$1:$K$65536,7,FALSE)," ") -> DC | L31: =IF(A31>0,VLOOKUP(A31,[1]SE!$A$1:$K$65536,8,FALSE)," ") -> 0 | M31: =IF(A31>0,VLOOKUP(A31,[1]SE!$A$1:$K$65536,4,FALSE)," ") -> Telemecanique | N31: =IF(A31>0,VLOOKUP(A31,[1]SE!$A$1:$K$65536,10,FALSE)," ") -> ATEX21 | O31: =IF(A31>0,VLOOKUP(A31,[1]SE!$A$1:$K$65536,11,FALSE)," ") -> cable 2 m | P31: TRM CHN
A33: SE0110 | B33: BE0808C | C33: TM F02.1 | D33: 2 | E33: LIMIT SWITCH | I33: =IF(A33>0,VLOOKUP(A33,[1]SE!$A$1:$K$65536,5,FALSE)," ") -> XS630B1PAL2EX | J33: =IF(A33>0,VLOOKUP(A33,[1]SE!$A$1:$K$65536,6,FALSE)," ") -> 10 ÷ 48 | K33: =IF(A33>0,VLOOKUP(A33,[1]SE!$A$1:$K$65536,7,FALSE)," ") -> DC | L33: =IF(A33>0,VLOOKUP(A33,[1]SE!$A$1:$K$65536,8,FALSE)," ") -> 0 | M33: =IF(A33>0,VLOOKUP(A33,[1]SE!$A$1:$K$65536,4,FALSE)," ") -> Telemecanique | N33: =IF(A33>0,VLOOKUP(A33,[1]SE!$A$1:$K$65536,10,FALSE)," ") -> ATEX21 | O33: =IF(A33>0,VLOOKUP(A33,[1]SE!$A$1:$K$65536,11,FALSE)," ") -> cable 2 m | P33: TRM CHN
A35: SE0110 | B35: BE0809C | C35: TM F03 | D35: 1 | E35: SPEED CONTROL | I35: =IF(A35>0,VLOOKUP(A35,[1]SE!$A$1:$K$65536,5,FALSE)," ") -> XS630B1PAL2EX | J35: =IF(A35>0,VLOOKUP(A35,[1]SE!$A$1:$K$65536,6,FALSE)," ") -> 10 ÷ 48 | K35: =IF(A35>0,VLOOKUP(A35,[1]SE!$A$1:$K$65536,7,FALSE)," ") -> DC | L35: =IF(A35>0,VLOOKUP(A35,[1]SE!$A$1:$K$65536,8,FALSE)," ") -> 0 | M35: =IF(A35>0,VLOOKUP(A35,[1]SE!$A$1:$K$65536,4,FALSE)," ") -> Telemecanique | N35: =IF(A35>0,VLOOKUP(A35,[1]SE!$A$1:$K$65536,10,FALSE)," ") -> ATEX21 | O35: =IF(A35>0,VLOOKUP(A35,[1]SE!$A$1:$K$65536,11,FALSE)," ") -> cable 2 m | P35: TRM CHN
A36: SE0020 | B36: BE0809C | C36: TM F03 | D36: 1 | E36: SAFETY CABLE LEFT | I36: =IF(A36>0,VLOOKUP(A36,[1]SE!$A$1:$K$65536,5,FALSE)," ") -> XY2CE2A250EX | J36: =IF(A36>0,VLOOKUP(A36,[1]SE!$A$1:$K$65536,6,FALSE)," ") -> 0 | K36: =IF(A36>0,VLOOKUP(A36,[1]SE!$A$1:$K$65536,7,FALSE)," ") -> 0 | L36: =IF(A36>0,VLOOKUP(A36,[1]SE!$A$1:$K$65536,8,FALSE)," ") -> 0 | M36: =IF(A36>0,VLOOKUP(A36,[1]SE!$A$1:$K$65536,4,FALSE)," ") -> Telemecanique | N36: =IF(A36>0,VLOOKUP(A36,[1]SE!$A$1:$K$65536,10,FALSE)," ") -> ATEX21 | O36: =IF(A36>0,VLOOKUP(A36,[1]SE!$A$1:$K$65536,11,FALSE)," ") -> Nr. 1 x side Max. <=40 mt. ==> nr. 2 | P36: TRM CHN
A37: SE0019 | B37: BE0809C | C37: TM F03 | D37: 1 | E37: SAFETY CABLE RIGHT | I37: =IF(A37>0,VLOOKUP(A37,[1]SE!$A$1:$K$65536,5,FALSE)," ") -> XY2CE1A250EX | J37: =IF(A37>0,VLOOKUP(A37,[1]SE!$A$1:$K$65536,6,FALSE)," ") -> 0 | K37: =IF(A37>0,VLOOKUP(A37,[1]SE!$A$1:$K$65536,7,FALSE)," ") -> 0 | L37: =IF(A37>0,VLOOKUP(A37,[1]SE!$A$1:$K$65536,8,FALSE)," ") -> 0 | M37: =IF(A37>0,VLOOKUP(A37,[1]SE!$A$1:$K$65536,4,FALSE)," ") -> Telemecanique | N37: =IF(A37>0,VLOOKUP(A37,[1]SE!$A$1:$K$65536,10,FALSE)," ") -> ATEX21 | O37: =IF(A37>0,VLOOKUP(A37,[1]SE!$A$1:$K$65536,11,FALSE)," ") -> Nr. 1 x side Max. <=40 mt. ==> nr. 2 | P37: TRM CHN
A38: SE0018 | B38: BE0809C | C38: TM F03 | D38: 4 | E38: ANTI SIDE-SKID CONTROL | I38: =IF(A38>0,VLOOKUP(A38,[1]SE!$A$1:$K$65536,5,FALSE)," ") -> XCRT115EX | J38: =IF(A38>0,VLOOKUP(A38,[1]SE!$A$1:$K$65536,6,FALSE)," ") -> 0 | K38: =IF(A38>0,VLOOKUP(A38,[1]SE!$A$1:$K$65536,7,FALSE)," ") -> 0 | L38: =IF(A38>0,VLOOKUP(A38,[1]SE!$A$1:$K$65536,8,FALSE)," ") -> 0 | M38: =IF(A38>0,VLOOKUP(A38,[1]SE!$A$1:$K$65536,4,FALSE)," ") -> Telemecanique | N38: =IF(A38>0,VLOOKUP(A38,[1]SE!$A$1:$K$65536,10,FALSE)," ") -> ATEX21 | O38: =IF(A38>0,VLOOKUP(A38,[1]SE!$A$1:$K$65536,11,FALSE)," ") -> 0 | P38: TRM CHN
A39: SE0046-15 | B39: BE0809C | C39: TM F03 | D39: 1 | E39: LEVEL SENSOR | I39: =IF(A39>0,VLOOKUP(A39,[1]SE!$A$1:$K$65536,5,FALSE)," ") -> VB62.GXTGDRAMX | J39: =IF(A39>0,VLOOKUP(A39,[1]SE!$A$1:$K$65536,6,FALSE)," ") -> 24 | K39: =IF(A39>0,VLOOKUP(A39,[1]SE!$A$1:$K$65536,7,FALSE)," ") -> DC | L39: =IF(A39>0,VLOOKUP(A39,[1]SE!$A$1:$K$65536,8,FALSE)," ") -> 0 | M39: =IF(A39>0,VLOOKUP(A39,[1]SE!$A$1:$K$65536,4,FALSE)," ") -> Vega | N39: =IF(A39>0,VLOOKUP(A39,[1]SE!$A$1:$K$65536,10,FALSE)," ") -> ATEX22 | O39: =IF(A39>0,VLOOKUP(A39,[1]SE!$A$1:$K$65536,11,FALSE)," ") -> L= 1500mm | P39: TRM ITY
A41: SE0110 | B41: BE0810C | C41: TM F04 | D41: 2 | E41: LIMIT SWITCH | I41: =IF(A41>0,VLOOKUP(A41,[1]SE!$A$1:$K$65536,5,FALSE)," ") -> XS630B1PAL2EX | J41: =IF(A41>0,VLOOKUP(A41,[1]SE!$A$1:$K$65536,6,FALSE)," ") -> 10 ÷ 48 | K41: =IF(A41>0,VLOOKUP(A41,[1]SE!$A$1:$K$65536,7,FALSE)," ") -> DC | L41: =IF(A41>0,VLOOKUP(A41,[1]SE!$A$1:$K$65536,8,FALSE)," ") -> 0 | M41: =IF(A41>0,VLOOKUP(A41,[1]SE!$A$1:$K$65536,4,FALSE)," ") -> Telemecanique | N41: =IF(A41>0,VLOOKUP(A41,[1]SE!$A$1:$K$65536,10,FALSE)," ") -> ATEX21 | O41: =IF(A41>0,VLOOKUP(A41,[1]SE!$A$1:$K$65536,11,FALSE)," ") -> cable 2 m | P41: TRM CHN
... A93: SE0052-03 | B93: BE0823C | C93: TM F16 | D93: 6 | E93: LEVEL SENSOR | I93: =IF(A93>0,VLOOKUP(A93,[1]SE!$A$1:$K$65536,5,FALSE)," ") -> VB63.GXAGDRAMX | J93: =IF(A93>0,VLOOKUP(A93,[1]SE!$A$1:$K$65536,6,FALSE)," ") -> 24 | K93: =IF(A93>0,VLOOKUP(A93,[1]SE!$A$1:$K$65536,7,FALSE)," ") -> DC | L93: =IF(A93>0,VLOOKUP(A93,[1]SE!$A$1:$K$65536,8,FALSE)," ") -> 0 | M93: =IF(A93>0,VLOOKUP(A93,[1]SE!$A$1:$K$65536,4,FALSE)," ") -> Vega | N93: =IF(A93>0,VLOOKUP(A93,[1]SE!$A$1:$K$65536,10,FALSE)," ") -> ATEX20 | O93: =IF(A93>0,VLOOKUP(A93,[1]SE!$A$1:$K$65536,11,FALSE)," ") -> L=300 mm | P93: TRM ITY
A96: ADDITIONAL SENSORS - SEE RELATED TECNICAL DOCUMENTS (I.E. ADDITIONAL MOTORS FOR: MOVING FLOOR, LUBRICATION SYSTEMS, FAN BLADES)
A97: TECH.DOC. NR. | B97: TRASMEC JOB N° | C97: LAYOUT POSITION | D97: QTY | E97: DESCRIPTION | O97: NOTE
B101: BE0815C | C101: TM F10 | D101: 1 | E101: Sensors on hydraulic unit (SEE SCHEME FM000086-00) | P101: TRM ITY
O103: =IF(A103>0,VLOOKUP(A103,[1]SE!$A$1:$K$65536,11,FALSE)," ")

Sheet Foglio2
